Workbook

Sheet Index
A1: 삼성전기 투자심사 모델
A2: tools/build_excel.py가 model.html에서 생성. 직접 고치지 말 것 — 다음 빌드에 덮인다.
A4: 시트 | B4: 내용
A5: Index | B5: 이 시트
A6: Control | B6: 모델 개요·전역 설정
A7: Assumptions | B7: 가정변수 일람과 근거
A8: Model | B8: 계정 트리 × 연도. 수식이 살아있는 본체
A9: Formula Audit | B9: 모델 원식 ↔ 셀 수식 대조
A10: Structure | B10: 트리 구조·깊이·행 배치
A11: Checks | B11: 부모 = 자식 합 정합 검증
A12: Metadata | B12: 빌드 정보
A14: 셀 색 규약
A15: 파랑 글자 | B15: 하드코딩 입력값 — 여기만 고친다
A16: 검정 글자 | B16: 수식
A17: 회색 배경 | B17: 실적(Historical) 구간 — 공시 확정값

Sheet Control
A1: 컨트롤
A2: 가정을 바꾸려면 Assumptions 시트가 아니라 Model 시트의 파랑 셀을 고친다. Model이 계산의 단일 출처다.
A4: 모델 | B4: 삼성전기 투자심사 모델
A5: 통화 단위 | B5: 억원
A6: 범위 | B6: 매출 → 영업이익 → 밸류에이션
A7: 실적 연도 수 (HIST_N) | B7: 5
A8: 추정 연도 수 | B8: 5
A9: 첫 연도 | B9: 2021
A10: 마지막 연도 | B10: 2030

Sheet Assumptions
A1: 가정변수 일람
A2: 파랑 = 하드코딩 입력값. 근거 열의 대괄호 태그가 객관/주관 구분이다.
D3: 실적 | E3: 실적 | F3: 실적 | G3: 실적 | H3: 실적 | I3: 추정 | J3: 추정 | K3: 추정 | L3: 추정 | M3: 추정
A4: 계정 | B4: 노드 id | C4: 단위 | D4: 2021A | E4: 2022A | F4: 2023A | G4: 2024A | H4: 2025A | I4: 2026E | J4: 2027E | K4: 2028E | L4: 2029E | M4: 2030E | N4: 근거
A5: 목표 EV/EBITDA | B5: target_ev_ebitda | C5: 배 | D5: 18 | E5: 18 | F5: 18 | G5: 18 | H5: 18 | I5: 18 | J5: 18 | K5: 18 | L5: 18 | M5: 18 | N5: [주관·시나리오] **2026-08-28 15배 → 18배 상향.** 근거는 해외 피어다. 2026 부문 EBITDA 비중(컴포넌트 55.2% · 패키지 32.2% · 광학 12.7%)으로 피어 배수를 가중하면 22.9배가 나온다 (MLCC 무라타·야게오 평균 24.0 · FC-BGA 이비덴·신코덴키 평균 26.7 · 광학 LG이노텍 8.3). 그러나 이 배수들은 **지금 시점의 TTM**이고 목표배수는 2030년에 적용하는 값이다. 테마 프리미엄이 5년 뒤에도 유지된다는 가정은 두지 않았다. 가중평균 22.9배와 국내 AI 기판 2026E 상단(21.3배) 아래인 18배를 택했다. 이 모델에서 가장 강력한 단일 가정이다. 값을 두 배로 하면 적정가치도 두 배가 된다. 국내 부품사 역사적 중간값은 5~8배 수준이나, 전장·서버 믹스 전환과 AI 수요를 반영해 프리미엄을 적용했다. 현재 주가가 함의하는 배수는 심사 뷰에서 역산해 함께 본다.
A6: 순이익 실적 마스크 | B6: ni_hist | D6: 1 | E6: 1 | F6: 1 | G6: 1 | H6: 1 | I6: 0 | J6: 0 | K6: 0 | L6: 0 | M6: 0 | N6: [객관] 실적 연도 표시(1). 순이익은 적자 연도가 있어 "실적 > 0" 관용구를 쓸 수 없다 — LGD·삼성전자 DS에서 확립한 hist 마스크 패턴.
A7: 순이익 실적 | B7: ni_actual | C7: 억원 | D7: 8924.4532 | E7: 9805.5164 | F7: 4229.5671 | G7: 6791.3007 | H7: 7061.1317 | I7: 0 | J7: 0 | K7: 0 | L7: 0 | M7: 0 | N7: [객관] 연결 지배주주 순이익 확정값 (사업보고서 연결포괄손익계산서).
A8: 영업외손익 | B8: nonop | C8: 억원 | D8: 44.361211 | E8: 39.921635 | F8: -973.06898 | G8: 622.90189 | H8: -174.99806 | I8: -100 | J8: -100 | K8: -100 | L8: -100 | M8: -100 | N8: [주관 추정 · 실적은 공시값] 영업외손익 = 세전이익 − 영업이익. 실적 +44/+40/−973/+623/−175억 — 금융·기타손익이 해마다 튄다. 추정은 5년 평균(−88억) 부근 **−100억 고정**.
A9: 실효세율 | B9: tax_rate | C9: % | D9: 0 | E9: 0 | F9: 0 | G9: 0 | H9: 0 | I9: 0.18 | J9: 0.18 | K9: 0.18 | L9: 0.18 | M9: 0.18 | N9: [주관] 실효세율. 실적 27.7/13.8/15.2/16.6/18.3% — 2021을 빼면 평균 16%. 여유를 둬 18%.
A10: 지배지분 비율 | B10: ctrl_ratio | C10: % | D10: 0 | E10: 0 | F10: 0 | G10: 0 | H10: 0 | I10: 0.965 | J10: 0.965 | K10: 0.965 | L10: 0.965 | M10: 0.965 | N10: [주관] 지배지분 비율. 실적 97.5/98.7/93.9/96.6/96.6% — 96.5% 고정.
A11: 상장주식수 | B11: shares | C11: 백만주 | D11: 74.693696 | E11: 74.693696 | F11: 74.693696 | G11: 74.693696 | H11: 74.693696 | I11: 74.693696 | J11: 74.693696 | K11: 74.693696 | L11: 74.693696 | M11: 74.693696 | N11: [객관] 상장 보통주 74,693,696주(2025년말) 고정. 기말 단순 기준 — 공시 기본EPS(가중평균·우선주 구분)와 계산 기준이 다르다.
A12: DPS 실적 | B12: dps_a | C12: 원 | D12: 2100 | E12: 2100 | F12: 1150 | G12: 1800 | H12: 2350 | I12: 0 | J12: 0 | K12: 0 | L12: 0 | M12: 0 | N12: [객관] 보통주 주당 현금배당. 실적 2,100/2,100/1,150/1,800/2,350원 (배당에 관한 사항).
A13: 배당성향 | B13: payout | C13: % | D13: 0 | E13: 0 | F13: 0 | G13: 0 | H13: 0 | I13: 0.25 | J13: 0.25 | K13: 0.25 | L13: 0.25 | M13: 0.25 | N13: [주관] 배당성향. 실적 17.8/16.2/20.6/20.0/25.2% — **25% 유지** 가정. DPS = EPS × 성향이라 이익이 크면 배당도 같이 큰다.
A14: 컴포넌트 실적 | B14: comp_actual | C14: 억원 | D14: 47718.3 | E14: 41322.83 | F14: 39030.22 | G14: 44620.5 | H14: 51985.01 | I14: 0 | J14: 0 | K14: 0 | L14: 0 | M14: 0 | N14: [객관·확정] 사업보고서 영업부문 주석. 2021~2022는 최초 공시 기준, 2023~2025는 중단영업 재작성 기준(컴포넌트는 재작성 영향 없음). 추정 연도는 0 — 0이면 성장률 경로로 넘어간다.
A15: 컴포넌트 물량 성장률 | B15: comp_vol_g | C15: % | D15: 0 | E15: 0 | F15: 0 | G15: 0 | H15: 0 | I15: 0.14 | J15: 0.09 | K15: 0.07 | L15: 0.05 | M15: 0.05 | N15: [주관·시나리오] **2026-08-28 상향** (기존 8/7/6/5/5%). 2026 상반기 확정 매출 30,579억, 전년 동기 대비 +22.5%. 계절성(H2/H1 평균 1.063)과 YoY 연장 두 방법이 FY2026을 63,079억·63,663억으로 서로 1% 안에서 일치해 63,371억을 채택했고, 이는 2025년 대비 +21.9%다. 물량 14% × 단가 7%로 나눴다. 2027 이후는 기저가 커지므로 더 가파르게 체감시킨다. 출하 수량 성장률. 전장(대당 탑재량 상승)과 서버·AI (고용량 제품)가 구조적 성장축이고 IT는 사이클성. 공시가 출하 수량을 주지 않아 물량과 단가의 분리는 추정이며, 이 슬라이더가 그 가정이다.
A16: 컴포넌트 단가·믹스 성장률 | B16: comp_price_g | C16: % | D16: 0 | E16: 0 | F16: 0 | G16: 0 | H16: 0 | I16: 0.07 | J16: 0.04 | K16: 0.03 | L16: 0.02 | M16: 0.02 | N16: [주관·시나리오] **2026-08-28 상향** (기존 4/3/3/2/2%). AI 서버용 고용량 제품 믹스 상승분을 단가 쪽에 배분했다. 공시가 부문별 출하 수량을 주지 않아 물량·단가 분해는 여전히 판단이다 — 합계 증가율만 실적에서 확정된다. 블렌디드 단가 상승률. 전장·서버 비중이 오르면 같은 수량에도 매출이 오른다. 범용 IT 제품은 공급과잉 시 하락 압력. 비용 레이어의 부문 마진과 공유하는 드라이버 — 믹스 개선은 매출과 마진을 함께 끌어올린다.
A17: 광학 실적 | B17: optics_actual | C17: 억원 | D17: 32240.56 | E17: 32039.5 | F17: 32720.12 | G17: 37973.96 | H17: 38142.05 | I17: 0 | J17: 0 | K17: 0 | L17: 0 | M17: 0 | N17: [객관·확정] 사업보고서 영업부문 주석. 2021~2022는 최초 공시(광학통신솔루션), 2023~2025는 중단영업 재작성 기준(광학솔루션). 재작성 차이는 전액 이 부문에 있으며 2023 기준 170억(적자 사업) — 총매출의 0.19%.
A18: 광학 물량 성장률 | B18: optics_vol_g | C18: % | D18: 0 | E18: 0 | F18: 0 | G18: 0 | H18: 0 | I18: 0.03 | J18: 0.01 | K18: 0.01 | L18: 0 | M18: 0 | N18: [주관·시나리오] **2026-08-28 소폭 상향** (기존 1/1/1/0/0%). 상반기 +7.6%로 기존 가정을 웃돌았으나, 이 부문은 계절성이 역방향(H2/H1 0.879)이라 상반기 강세를 연간으로 그대로 연장하지 않았다. FY2026 40,359억(+5.8%). 모듈 출하량 성장률 = 고객사 물량 × 고객사 내 점유율. 두 변수가 곱으로 들어가 하방 변동이 증폭된다. 경쟁사 진입이 이 부문 최대 위험이며 Bear 시나리오에서 가장 크게 흔들 변수다.
... A35: 순차입금 | B35: net_debt | C35: 억원 | D35: -1928 | E35: -2558 | F35: -1477 | G35: -4554 | H35: -5094 | I35: -5094 | J35: -5094 | K35: -5094 | L35: -5094 | M35: -5094 | N35: [객관·실적 확정 / 추정 구간은 보수적 고정] 총차입금(단기+유동성장기+장기) − 현금및현금성자산. 전 기간 음수 = 순현금이다. 실적: −1,928 → −2,558 → −1,477 → −4,554 → −5,094억원. 추정 구간은 2025년 수준으로 고정했다 — 이익 창출로 순현금이 더 쌓이는 것이 자연스러우나 배당·증설 계획이 공시되지 않아 보수적으로 두었다. 현재 시가총액의 0.5% 규모라 밸류에이션에 미치는 영향은 미미하다. 리스부채는 제외했다.

Sheet Model
A1: 삼성전기 투자심사 모델
A2: 단위 억원 · 실적 5개년 + 추정 5개년
D3: 실적 | E3: 실적 | F3: 실적 | G3: 실적 | H3: 실적 | I3: 추정 | J3: 추정 | K3: 추정 | L3: 추정 | M3: 추정
A4: 계정 | B4: 노드 id | C4: 단위 | D4: 2021A | E4: 2022A | F4: 2023A | G4: 2024A | H4: 2025A | I4: 2026E | J4: 2027E | K4: 2028E | L4: 2029E | M4: 2030E
A5: 적정 시가총액 | B5: root | C5: 억원 | D5: =(D6-D57) | E5: =(E6-E57) | F5: =(F6-F57) | G5: =(G6-G57) | H5: =(H6-H57) | I5: =(I6-I57) | J5: =(J6-J57) | K5: =(K6-K57) | ... M5: =(M6-M57)
A6: 사업가치 (EV) | B6: ev_value | C6: 억원 | D6: =(D8*D7) | E6: =(E8*E7) | F6: =(F8*F7) | G6: =(G8*G7) | H6: =(H8*H7) | I6: =(I8*I7) | J6: =(J8*J7) | K6: =(K8*K7) | ... M6: =(M8*M7)
A7: 목표 EV/EBITDA | B7: target_ev_ebitda | C7: 배 | D7: 18 | E7: 18 | F7: 18 | G7: 18 | H7: 18 | I7: 18 | J7: 18 | K7: 18 | L7: 18 | M7: 18
A8: EBITDA | B8: ebitda | C8: 억원 | D8: =(D10+D9) | E8: =(E10+E9) | F8: =(F10+F9) | G8: =(G10+G9) | H8: =(H10+H9) | I8: =(I10+I9) | J8: =(J10+J9) | K8: =(K10+K9) | ... M8: =(M10+M9)
A9: 감가상각비 합계 | B9: dep_total | C9: 억원 | D9: =((D37+D44)+D51) | E9: =((E37+E44)+E51) | F9: =((F37+F44)+F51) | G9: =((G37+G44)+G51) | H9: =((H37+H44)+H51) | I9: =((I37+I44)+I51) | J9: =((J37+J44)+J51) | K9: =((K37+K44)+K51) | ... M9: =((M37+M44)+M51)
A10: 영업이익 | B10: op_profit | C10: 억원 | D10: =(D22-D35) | E10: =(E22-E35) | F10: =(F22-F35) | G10: =(G22-G35) | H10: =(H22-H35) | I10: =(I22-I35) | J10: =(J22-J35) | K10: =(K22-K35) | ... M10: =(M22-M35)
A11: 지배주주 순이익 (참고) | B11: net_income | C11: 억원 | D11: =IF((D12>0),D13,(((D10+D14)*(1-D15))*D16)) | E11: =IF((E12>0),E13,(((E10+E14)*(1-E15))*E16)) | F11: =IF((F12>0),F13,(((F10+F14)*(1-F15))*F16)) | G11: =IF((G12>0),G13,(((G10+G14)*(1-G15))*G16)) | H11: =IF((H12>0),H13,(((H10+H14)*(1-H15))*H16)) | I11: =IF((I12>0),I13,(((I10+I14)*(1-I15))*I16)) | J11: =IF((J12>0),J13,(((J10+J14)*(1-J15))*J16)) | K11: =IF((K12>0),K13,(((K10+K14)*(1-K15))*K16)) | ... M11: =IF((M12>0),M13,(((M10+M14)*(1-M15))*M16))
A12: 순이익 실적 마스크 | B12: ni_hist | D12: 1 | E12: 1 | F12: 1 | G12: 1 | H12: 1 | I12: 0 | J12: 0 | K12: 0 | L12: 0 | M12: 0
A13: 순이익 실적 | B13: ni_actual | C13: 억원 | D13: 8924.4532 | E13: 9805.5164 | F13: 4229.5671 | G13: 6791.3007 | H13: 7061.1317 | I13: 0 | J13: 0 | K13: 0 | L13: 0 | M13: 0
A14: 영업외손익 | B14: nonop | C14: 억원 | D14: 44.361211 | E14: 39.921635 | F14: -973.06898 | G14: 622.90189 | H14: -174.99806 | I14: -100 | J14: -100 | K14: -100 | L14: -100 | M14: -100
A15: 실효세율 | B15: tax_rate | C15: % | D15: 0 | E15: 0 | F15: 0 | G15: 0 | H15: 0 | I15: 0.18 | J15: 0.18 | K15: 0.18 | L15: 0.18 | M15: 0.18
A16: 지배지분 비율 | B16: ctrl_ratio | C16: % | D16: 0 | E16: 0 | F16: 0 | G16: 0 | H16: 0 | I16: 0.965 | J16: 0.965 | K16: 0.965 | L16: 0.965 | M16: 0.965
A17: EPS (참고) | B17: eps | C17: 원 | D17: =((D11/D18)*100) | E17: =((E11/E18)*100) | F17: =((F11/F18)*100) | G17: =((G11/G18)*100) | H17: =((H11/H18)*100) | I17: =((I11/I18)*100) | J17: =((J11/J18)*100) | K17: =((K11/K18)*100) | ... M17: =((M11/M18)*100)
A18: 상장주식수 | B18: shares | C18: 백만주 | D18: 74.693696 | E18: 74.693696 | F18: 74.693696 | G18: 74.693696 | H18: 74.693696 | I18: 74.693696 | J18: 74.693696 | K18: 74.693696 | L18: 74.693696 | M18: 74.693696
A19: DPS (참고) | B19: dps | C19: 원 | D19: =IF((D12>0),D20,(D17*D21)) | E19: =IF((E12>0),E20,(E17*E21)) | F19: =IF((F12>0),F20,(F17*F21)) | G19: =IF((G12>0),G20,(G17*G21)) | H19: =IF((H12>0),H20,(H17*H21)) | I19: =IF((I12>0),I20,(I17*I21)) | J19: =IF((J12>0),J20,(J17*J21)) | K19: =IF((K12>0),K20,(K17*K21)) | ... M19: =IF((M12>0),M20,(M17*M21))
A20: DPS 실적 | B20: dps_a | C20: 원 | D20: 2100 | E20: 2100 | F20: 1150 | G20: 1800 | H20: 2350 | I20: 0 | J20: 0 | K20: 0 | L20: 0 | M20: 0
A21: 배당성향 | B21: payout | C21: % | D21: 0 | E21: 0 | F21: 0 | G21: 0 | H21: 0 | I21: 0.25 | J21: 0.25 | K21: 0.25 | L21: 0.25 | M21: 0.25
A22: 매출 | B22: total_revenue | C22: 억원 | D22: =((D23+D27)+D31) | E22: =((E23+E27)+E31) | F22: =((F23+F27)+F31) | G22: =((G23+G27)+G31) | H22: =((H23+H27)+H31) | I22: =((I23+I27)+I31) | J22: =((J23+J27)+J31) | K22: =((K23+K27)+K31) | ... M22: =((M23+M27)+M31)
A23: ① 컴포넌트 | B23: component_total | C23: 억원 | D23: =IF((D24>0),D24,((0*(1+D25))*(1+D26))) | E23: =IF((E24>0),E24,((D23*(1+E25))*(1+E26))) | F23: =IF((F24>0),F24,((E23*(1+F25))*(1+F26))) | G23: =IF((G24>0),G24,((F23*(1+G25))*(1+G26))) | H23: =IF((H24>0),H24,((G23*(1+H25))*(1+H26))) | I23: =IF((I24>0),I24,((H23*(1+I25))*(1+I26))) | J23: =IF((J24>0),J24,((I23*(1+J25))*(1+J26))) | K23: =IF((K24>0),K24,((J23*(1+K25))*(1+K26))) | L23: =IF((L24>0),L24,((K23*(1+L25))*(1+L26))) | M23: =IF((M24>0),M24,((L23*(1+M25))*(1+M26)))
A24: 컴포넌트 실적 | B24: comp_actual | C24: 억원 | D24: 47718.3 | E24: 41322.83 | F24: 39030.22 | G24: 44620.5 | H24: 51985.01 | I24: 0 | J24: 0 | K24: 0 | L24: 0 | M24: 0
A25: 컴포넌트 물량 성장률 | B25: comp_vol_g | C25: % | D25: 0 | E25: 0 | F25: 0 | G25: 0 | H25: 0 | I25: 0.14 | J25: 0.09 | K25: 0.07 | L25: 0.05 | M25: 0.05
A26: 컴포넌트 단가·믹스 성장률 | B26: comp_price_g | C26: % | D26: 0 | E26: 0 | F26: 0 | G26: 0 | H26: 0 | I26: 0.07 | J26: 0.04 | K26: 0.03 | L26: 0.02 | M26: 0.02
A27: ② 광학솔루션 | B27: optics_total | C27: 억원 | D27: =IF((D28>0),D28,((0*(1+D29))*(1+D30))) | E27: =IF((E28>0),E28,((D27*(1+E29))*(1+E30))) | F27: =IF((F28>0),F28,((E27*(1+F29))*(1+F30))) | G27: =IF((G28>0),G28,((F27*(1+G29))*(1+G30))) | H27: =IF((H28>0),H28,((G27*(1+H29))*(1+H30))) | I27: =IF((I28>0),I28,((H27*(1+I29))*(1+I30))) | J27: =IF((J28>0),J28,((I27*(1+J29))*(1+J30))) | K27: =IF((K28>0),K28,((J27*(1+K29))*(1+K30))) | L27: =IF((L28>0),L28,((K27*(1+L29))*(1+L30))) | M27: =IF((M28>0),M28,((L27*(1+M29))*(1+M30)))
A28: 광학 실적 | B28: optics_actual | C28: 억원 | D28: 32240.56 | E28: 32039.5 | F28: 32720.12 | G28: 37973.96 | H28: 38142.05 | I28: 0 | J28: 0 | K28: 0 | L28: 0 | M28: 0
A29: 광학 물량 성장률 | B29: optics_vol_g | C29: % | D29: 0 | E29: 0 | F29: 0 | G29: 0 | H29: 0 | I29: 0.03 | J29: 0.01 | K29: 0.01 | L29: 0 | M29: 0
A30: 광학 단가·믹스 성장률 | B30: optics_price_g | C30: % | D30: 0 | E30: 0 | F30: 0 | G30: 0 | H30: 0 | I30: 0.027 | J30: 0.02 | K30: 0.02 | L30: 0.02 | M30: 0.01
A31: ③ 패키지솔루션 | B31: package_total | C31: 억원 | D31: =IF((D32>0),D32,((0*(1+D33))*(1+D34))) | E31: =IF((E32>0),E32,((D31*(1+E33))*(1+E34))) | F31: =IF((F32>0),F32,((E31*(1+F33))*(1+F34))) | G31: =IF((G32>0),G32,((F31*(1+G33))*(1+G34))) | H31: =IF((H32>0),H32,((G31*(1+H33))*(1+H34))) | I31: =IF((I32>0),I32,((H31*(1+I33))*(1+I34))) | J31: =IF((J32>0),J32,((I31*(1+J33))*(1+J34))) | K31: =IF((K32>0),K32,((J31*(1+K33))*(1+K34))) | L31: =IF((L32>0),L32,((K31*(1+L33))*(1+L34))) | M31: =IF((M32>0),M32,((L31*(1+M33))*(1+M34)))
A32: 패키지 실적 | B32: pkg_actual | C32: 억원 | D32: 16791.5 | E32: 20883.19 | F32: 17173.78 | G32: 20346.57 | H32: 23017.53 | I32: 0 | J32: 0 | K32: 0 | L32: 0 | M32: 0
A33: 패키지 물량 성장률 | B33: pkg_vol_g | C33: % | D33: 0 | E33: 0 | F33: 0 | G33: 0 | H33: 0 | I33: 0.26 | J33: 0.16 | K33: 0.12 | L33: 0.09 | M33: 0.07
A34: 패키지 단가·믹스 성장률 | B34: pkg_price_g | C34: % | D34: 0 | E34: 0 | F34: 0 | G34: 0 | H34: 0 | I34: 0.12 | J34: 0.05 | K34: 0.03 | L34: 0.02 | M34: 0.02
A35: 비용 | B35: total_cost | C35: 억원 | D35: =((D36+D43)+D50) | E35: =((E36+E43)+E50) | F35: =((F36+F43)+F50) | G35: =((G36+G43)+G50) | H35: =((H36+H43)+H50) | I35: =((I36+I43)+I50) | J35: =((J36+J43)+J50) | K35: =((K36+K43)+K50) | ... M35: =((M36+M43)+M50)
A36: ① 컴포넌트 비용 | B36: comp_cost | C36: 억원 | D36: =(D37+D40) | E36: =(E37+E40) | F36: =(F37+F40) | G36: =(G37+G40) | H36: =(H37+H40) | I36: =(I37+I40) | J36: =(J37+J40) | K36: =(K37+K40) | ... M36: =(M37+M40)
A37: 컴포넌트 감가상각비 | B37: comp_dep | C37: 억원 | D37: =IF((D38>0),D38,(0*(1+D39))) | E37: =IF((E38>0),E38,(D37*(1+E39))) | F37: =IF((F38>0),F38,(E37*(1+F39))) | G37: =IF((G38>0),G38,(F37*(1+G39))) | H37: =IF((H38>0),H38,(G37*(1+H39))) | I37: =IF((I38>0),I38,(H37*(1+I39))) | J37: =IF((J38>0),J38,(I37*(1+J39))) | K37: =IF((K38>0),K38,(J37*(1+K39))) | L37: =IF((L38>0),L38,(K37*(1+L39))) | M37: =IF((M38>0),M38,(L37*(1+M39)))
A38: 컴포넌트 감가 실적 | B38: comp_dep_actual | C38: 억원 | D38: 5416.62 | E38: 5699 | F38: 4921.87 | G38: 4242.86 | H38: 4392.41 | I38: 0 | J38: 0 | K38: 0 | L38: 0 | M38: 0
A39: 컴포넌트 감가 증가율 | B39: comp_dep_g | C39: % | D39: 0 | E39: 0 | F39: 0 | G39: 0 | H39: 0 | I39: -0.03 | J39: 0.02 | K39: 0.02 | L39: 0.01 | M39: 0.01
A40: 컴포넌트 기타비용 | B40: comp_other | C40: 억원 | D40: =IF((D41>0),D41,(D23*D42)) | E40: =IF((E41>0),E41,(E23*E42)) | F40: =IF((F41>0),F41,(F23*F42)) | G40: =IF((G41>0),G41,(G23*G42)) | H40: =IF((H41>0),H41,(H23*H42)) | I40: =IF((I41>0),I41,(I23*I42)) | J40: =IF((J41>0),J41,(J23*J42)) | K40: =IF((K41>0),K41,(K23*K42)) | ... M40: =IF((M41>0),M41,(M23*M42))
...

Sheet Formula Audit
A1: 수식 감사
A2: 모델 원식 ↔ Excel 셀 수식 대조. 변환은 엔진의 astToExcel이 담당한다.
A4: 노드 id | B4: 계정 | C4: 행 | D4: 모델 원식 | E4: 첫 추정연도 셀 수식
A5: root | B5: 적정 시가총액 | C5: 5 | D5: ev_value - net_debt | E5: '=(I6-I57)
A6: ev_value | B6: 사업가치 (EV) | C6: 6 | D6: ebitda * target_ev_ebitda | E6: '=(I8*I7)
A7: ebitda | B7: EBITDA | C7: 8 | D7: op_profit + dep_total | E7: '=(I10+I9)
A8: dep_total | B8: 감가상각비 합계 | C8: 9 | D8: comp_dep + optics_dep + pkg_dep | E8: '=((I37+I44)+I51)
A9: op_profit | B9: 영업이익 | C9: 10 | D9: total_revenue - total_cost | E9: '=(I22-I35)
A10: net_income | B10: 지배주주 순이익 (참고) | C10: 11 | D10: IF(ni_hist > 0, ni_actual, (op_profit + nonop) * (1 - tax_rate) * ctrl_ratio) | E10: '=IF((I12>0),I13,(((I10+I14)*(1-I15))*I16))
A11: eps | B11: EPS (참고) | C11: 17 | D11: net_income / shares * 100 | E11: '=((I11/I18)*100)
A12: dps | B12: DPS (참고) | C12: 19 | D12: IF(ni_hist > 0, dps_a, eps * payout) | E12: '=IF((I12>0),I20,(I17*I21))
A13: total_revenue | B13: 매출 | C13: 22 | D13: component_total + optics_total + package_total | E13: '=((I23+I27)+I31)
A14: component_total | B14: ① 컴포넌트 | C14: 23 | D14: IF(comp_actual > 0, comp_actual, PREV(component_total) * (1 + comp_vol_g) * (1 + comp_price_g)) | E14: '=IF((I24>0),I24,((H23*(1+I25))*(1+I26)))
A15: optics_total | B15: ② 광학솔루션 | C15: 27 | D15: IF(optics_actual > 0, optics_actual, PREV(optics_total) * (1 + optics_vol_g) * (1 + optics_price_g)) | E15: '=IF((I28>0),I28,((H27*(1+I29))*(1+I30)))
A16: package_total | B16: ③ 패키지솔루션 | C16: 31 | D16: IF(pkg_actual > 0, pkg_actual, PREV(package_total) * (1 + pkg_vol_g) * (1 + pkg_price_g)) | E16: '=IF((I32>0),I32,((H31*(1+I33))*(1+I34)))
... A26: pkg_other | B26: 패키지 기타비용 | C26: 54 | D26: IF(pkg_other_actual > 0, pkg_other_actual, package_total * pkg_other_ratio) | E26: '=IF((I55>0),I55,(I31*I56))

Sheet Structure
A1: 트리 구조
A3: 노드 id | B3: 계정 | C3: 깊이 | D3: 유형 | E3: 합계형 | F3: 행 | G3: 단위
A4: root | B4: 적정 시가총액 | C4: 0 | D4: computed | F4: 5 | G4: 억원
A5: ev_value | B5: 사업가치 (EV) | C5: 1 | D5: computed | F5: 6 | G5: 억원
A6: target_ev_ebitda | B6: 목표 EV/EBITDA | C6: 2 | D6: input | F6: 7 | G6: 배
A7: ebitda | B7: EBITDA | C7: 2 | D7: computed | E7: Y | F7: 8 | G7: 억원
A8: dep_total | B8: 감가상각비 합계 | C8: 3 | D8: computed | F8: 9 | G8: 억원
A9: op_profit | B9: 영업이익 | C9: 3 | D9: computed | F9: 10 | G9: 억원
A10: net_income | B10: 지배주주 순이익 (참고) | C10: 4 | D10: computed | F10: 11 | G10: 억원
A11: ni_hist | B11: 순이익 실적 마스크 | C11: 5 | D11: input | F11: 12
A12: ni_actual | B12: 순이익 실적 | C12: 5 | D12: input | F12: 13 | G12: 억원
A13: nonop | B13: 영업외손익 | C13: 5 | D13: input | F13: 14 | G13: 억원
A14: tax_rate | B14: 실효세율 | C14: 5 | D14: input | F14: 15 | G14: %
A15: ctrl_ratio | B15: 지배지분 비율 | C15: 5 | D15: input | F15: 16 | G15: %
A16: eps | B16: EPS (참고) | C16: 5 | D16: computed | F16: 17 | G16: 원
A17: shares | B17: 상장주식수 | C17: 6 | D17: input | F17: 18 | G17: 백만주
A18: dps | B18: DPS (참고) | C18: 6 | D18: computed | F18: 19 | G18: 원
A19: dps_a | B19: DPS 실적 | C19: 7 | D19: input | F19: 20 | G19: 원
A20: payout | B20: 배당성향 | C20: 7 | D20: input | F20: 21 | G20: %
A21: total_revenue | B21: 매출 | C21: 4 | D21: computed | E21: Y | F21: 22 | G21: 억원
A22: component_total | B22: ① 컴포넌트 | C22: 5 | D22: computed | F22: 23 | G22: 억원
A23: comp_actual | B23: 컴포넌트 실적 | C23: 6 | D23: input | F23: 24 | G23: 억원
A24: comp_vol_g | B24: 컴포넌트 물량 성장률 | C24: 6 | D24: input | F24: 25 | G24: %
A25: comp_price_g | B25: 컴포넌트 단가·믹스 성장률 | C25: 6 | D25: input | F25: 26 | G25: %
A26: optics_total | B26: ② 광학솔루션 | C26: 5 | D26: computed | F26: 27 | G26: 억원
A27: optics_actual | B27: 광학 실적 | C27: 6 | D27: input | F27: 28 | G27: 억원
A28: optics_vol_g | B28: 광학 물량 성장률 | C28: 6 | D28: input | F28: 29 | G28: %
A29: optics_price_g | B29: 광학 단가·믹스 성장률 | C29: 6 | D29: input | F29: 30 | G29: %
A30: package_total | B30: ③ 패키지솔루션 | C30: 5 | D30: computed | F30: 31 | G30: 억원
A31: pkg_actual | B31: 패키지 실적 | C31: 6 | D31: input | F31: 32 | G31: 억원
A32: pkg_vol_g | B32: 패키지 물량 성장률 | C32: 6 | D32: input | F32: 33 | G32: %
A33: pkg_price_g | B33: 패키지 단가·믹스 성장률 | C33: 6 | D33: input | F33: 34 | G33: %
A34: total_cost | B34: 비용 | C34: 4 | D34: computed | E34: Y | F34: 35 | G34: 억원
A35: comp_cost | B35: ① 컴포넌트 비용 | C35: 5 | D35: computed | E35: Y | F35: 36 | G35: 억원
A36: comp_dep | B36: 컴포넌트 감가상각비 | C36: 6 | D36: computed | F36: 37 | G36: 억원
A37: comp_dep_actual | B37: 컴포넌트 감가 실적 | C37: 7 | D37: input | F37: 38 | G37: 억원
A38: comp_dep_g | B38: 컴포넌트 감가 증가율 | C38: 7 | D38: input | F38: 39 | G38: %
A39: comp_other | B39: 컴포넌트 기타비용 | C39: 6 | D39: computed | F39: 40 | G39: 억원
A40: comp_other_actual | B40: 컴포넌트 기타비용 실적 | C40: 7 | D40: input | F40: 41 | G40: 억원
A41: comp_other_ratio | B41: 컴포넌트 기타비용률 | C41: 7 | D41: input | F41: 42 | G41: %
...

Sheet Checks
A1: 검증
A2: 합계형 노드의 부모값과 자식 합의 차이. 전 칸이 0이어야 한다.
D3: 실적 | E3: 실적 | F3: 실적 | G3: 실적 | H3: 실적 | I3: 추정 | J3: 추정 | K3: 추정 | L3: 추정 | M3: 추정
A4: 계정 | B4: 검사 | D4: 2021A | E4: 2022A | F4: 2023A | G4: 2024A | H4: 2025A | I4: 2026E | J4: 2027E | K4: 2028E | L4: 2029E | M4: 2030E
A5: EBITDA | B5: 부모 − 자식합 | D5: =ROUND(Model!D8-(Model!D9+Model!D10),6) | E5: =ROUND(Model!E8-(Model!E9+Model!E10),6) | F5: =ROUND(Model!F8-(Model!F9+Model!F10),6) | G5: =ROUND(Model!G8-(Model!G9+Model!G10),6) | H5: =ROUND(Model!H8-(Model!H9+Model!H10),6) | I5: =ROUND(Model!I8-(Model!I9+Model!I10),6) | J5: =ROUND(Model!J8-(Model!J9+Model!J10),6) | K5: =ROUND(Model!K8-(Model!K9+Model!K10),6) | ... M5: =ROUND(Model!M8-(Model!M9+Model!M10),6)
A6: 매출 | B6: 부모 − 자식합 | D6: =ROUND(Model!D22-(Model!D23+Model!D27+Model!D31),6) | E6: =ROUND(Model!E22-(Model!E23+Model!E27+Model!E31),6) | F6: =ROUND(Model!F22-(Model!F23+Model!F27+Model!F31),6) | G6: =ROUND(Model!G22-(Model!G23+Model!G27+Model!G31),6) | H6: =ROUND(Model!H22-(Model!H23+Model!H27+Model!H31),6) | I6: =ROUND(Model!I22-(Model!I23+Model!I27+Model!I31),6) | J6: =ROUND(Model!J22-(Model!J23+Model!J27+Model!J31),6) | K6: =ROUND(Model!K22-(Model!K23+Model!K27+Model!K31),6) | ... M6: =ROUND(Model!M22-(Model!M23+Model!M27+Model!M31),6)
A7: 비용 | B7: 부모 − 자식합 | D7: =ROUND(Model!D35-(Model!D36+Model!D43+Model!D50),6) | E7: =ROUND(Model!E35-(Model!E36+Model!E43+Model!E50),6) | F7: =ROUND(Model!F35-(Model!F36+Model!F43+Model!F50),6) | G7: =ROUND(Model!G35-(Model!G36+Model!G43+Model!G50),6) | H7: =ROUND(Model!H35-(Model!H36+Model!H43+Model!H50),6) | I7: =ROUND(Model!I35-(Model!I36+Model!I43+Model!I50),6) | J7: =ROUND(Model!J35-(Model!J36+Model!J43+Model!J50),6) | K7: =ROUND(Model!K35-(Model!K36+Model!K43+Model!K50),6) | ... M7: =ROUND(Model!M35-(Model!M36+Model!M43+Model!M50),6)
A8: ① 컴포넌트 비용 | B8: 부모 − 자식합 | D8: =ROUND(Model!D36-(Model!D37+Model!D40),6) | E8: =ROUND(Model!E36-(Model!E37+Model!E40),6) | F8: =ROUND(Model!F36-(Model!F37+Model!F40),6) | G8: =ROUND(Model!G36-(Model!G37+Model!G40),6) | H8: =ROUND(Model!H36-(Model!H37+Model!H40),6) | I8: =ROUND(Model!I36-(Model!I37+Model!I40),6) | J8: =ROUND(Model!J36-(Model!J37+Model!J40),6) | K8: =ROUND(Model!K36-(Model!K37+Model!K40),6) | ... M8: =ROUND(Model!M36-(Model!M37+Model!M40),6)
A9: ② 광학 비용 | B9: 부모 − 자식합 | D9: =ROUND(Model!D43-(Model!D44+Model!D47),6) | E9: =ROUND(Model!E43-(Model!E44+Model!E47),6) | F9: =ROUND(Model!F43-(Model!F44+Model!F47),6) | G9: =ROUND(Model!G43-(Model!G44+Model!G47),6) | H9: =ROUND(Model!H43-(Model!H44+Model!H47),6) | I9: =ROUND(Model!I43-(Model!I44+Model!I47),6) | J9: =ROUND(Model!J43-(Model!J44+Model!J47),6) | K9: =ROUND(Model!K43-(Model!K44+Model!K47),6) | ... M9: =ROUND(Model!M43-(Model!M44+Model!M47),6)
A10: ③ 패키지 비용 | B10: 부모 − 자식합 | D10: =ROUND(Model!D50-(Model!D51+Model!D54),6) | E10: =ROUND(Model!E50-(Model!E51+Model!E54),6) | F10: =ROUND(Model!F50-(Model!F51+Model!F54),6) | G10: =ROUND(Model!G50-(Model!G51+Model!G54),6) | H10: =ROUND(Model!H50-(Model!H51+Model!H54),6) | I10: =ROUND(Model!I50-(Model!I51+Model!I54),6) | J10: =ROUND(Model!J50-(Model!J51+Model!J54),6) | K10: =ROUND(Model!K50-(Model!K51+Model!K54),6) | ... M10: =ROUND(Model!M50-(Model!M51+Model!M54),6)
A12: 합계형 노드 수 | B12: 6

Sheet Metadata
A1: 빌드 정보
A3: 소스 | B3: model.html
A4: 소스 해시 (sha256 앞 16자리) | B4: 160d3a76e03562a5
A5: 빌더 | B5: tools/build_excel.py
A6: 수식 변환 | B6: 엔진 astToExcel (JS) — 파이썬은 배치만 한다
A7: 노드 수 | B7: 53
A8: 입력 노드 수 | B8: 31
A9: 연도 수 | B9: 10
A10: HIST_N | B10: 5
A11: 모델 id | B11: samsung_em_revenue
