Workbook

Sheet Index
A1: 케이엠더블유 투자심사 모델
A2: tools/build_excel.py가 model.html에서 생성. 직접 고치지 말 것 — 다음 빌드에 덮인다.
A4: 시트 | B4: 내용
A5: Index | B5: 이 시트
A6: Control | B6: 모델 개요·전역 설정
A7: Assumptions | B7: 가정변수 일람과 근거
A8: Model | B8: 계정 트리 × 연도. 수식이 살아있는 본체
A9: Formula Audit | B9: 모델 원식 ↔ 셀 수식 대조
A10: Structure | B10: 트리 구조·깊이·행 배치
A11: Checks | B11: 부모 = 자식 합 정합 검증
A12: Metadata | B12: 빌드 정보
A14: 셀 색 규약
A15: 파랑 글자 | B15: 하드코딩 입력값 — 여기만 고친다
A16: 검정 글자 | B16: 수식
A17: 회색 배경 | B17: 실적(Historical) 구간 — 공시 확정값

Sheet Control
A1: 컨트롤
A2: 가정을 바꾸려면 Assumptions 시트가 아니라 Model 시트의 파랑 셀을 고친다. Model이 계산의 단일 출처다.
A4: 모델 | B4: 케이엠더블유 투자심사 모델
A5: 통화 단위 | B5: 억원
A6: 범위 | B6: 품목 매출 → 영업이익 → 밸류에이션 (사이클 중립)
A7: 실적 연도 수 (HIST_N) | B7: 5
A8: 추정 연도 수 | B8: 5
A9: 첫 연도 | B9: 2021
A10: 마지막 연도 | B10: 2030

Sheet Assumptions
A1: 가정변수 일람
A2: 파랑 = 하드코딩 입력값. 근거 열의 대괄호 태그가 객관/주관 구분이다.
D3: 실적 | E3: 실적 | F3: 실적 | G3: 실적 | H3: 실적 | I3: 추정 | J3: 추정 | K3: 추정 | L3: 추정 | M3: 추정
A4: 계정 | B4: 노드 id | C4: 단위 | D4: 2021A | E4: 2022A | F4: 2023A | G4: 2024A | H4: 2025A | I4: 2026E | J4: 2027E | K4: 2028E | L4: 2029E | M4: 2030E | N4: 근거
A5: 목표 EV/EBITDA | B5: target_ev_ebitda | C5: 배 | D5: 8 | E5: 8 | F5: 8 | G5: 8 | H5: 8 | I5: 8 | J5: 8 | K5: 8 | L5: 8 | M5: 8 | N5: [주관·시나리오] 8배. 근거는 피어의 사이클 중립 구간 — 흑자 안정 쏠리드 2026E 11.0·Fwd 8.9배, LIG아큐버 6.8배, 성숙 유선(유비쿼스) 2.6배. 테마 상단(RFHIC 18.6배)을 상단 실적 추정에 곱하면 이중 계상이라 중간인 8배를 2030 정상화 EBITDA에 적용한다. Bull 10배 / Bear 6배.
A6: 순이익 실적 마스크 | B6: ni_hist | D6: 1 | E6: 1 | F6: 1 | G6: 1 | H6: 1 | I6: 0 | J6: 0 | K6: 0 | L6: 0 | M6: 0 | N6: [객관] 실적 연도 표시(1). 전 연도 적자라 hist 마스크 관용구를 쓴다.
A7: 순이익 실적 | B7: ni_actual | C7: 억원 | D7: -37.293762 | E7: -266.86463 | F7: -652.86676 | G7: -386.04141 | H7: -270.33047 | I7: 0 | J7: 0 | K7: 0 | L7: 0 | M7: 0 | N7: [객관] 연결 포괄손익계산서 확정값 (지배 = 전체, 비지배 0).
A8: 영업외손익 | B8: nonop | C8: 억원 | D8: 0 | E8: 0 | F8: 0 | G8: 0 | H8: 0 | I8: -85 | J8: -40 | K8: -25 | L8: -15 | M8: -10 | N8: [주관 추정] 실적 연도는 마스크가 덮으므로 추정 구간만 쓴다. 이자비용과 전환사채 파생 평가손이 지배 — 2026 상반기에만 영업외 −81억이 났다 (세전 −200.7 대 영업 −120.0). 2026년 −85억에서 차입 축소를 가정하며 −10억까지 완화. 조달이 늘면 이 가정부터 깨진다.
A9: 실효세율 | B9: tax_rate | C9: % | D9: 0.08 | E9: 0.08 | F9: 0.08 | G9: 0.08 | H9: 0.08 | I9: 0.08 | J9: 0.08 | K9: 0.08 | L9: 0.08 | M9: 0.08 | N9: [주관] 8%. 누적 결손금(2025말 이월결손 약 617억 + 세무상 결손)이 커서 흑자 전환 후 수년간 이월결손공제(한도 80%)로 실효세율이 법정세율을 크게 밑돈다. 적자 연도에는 마스크(실적) 또는 음수 이익에 곱해져 영향이 작다.
A10: 지배지분비율 | B10: ctrl_ratio | C10: % | D10: 1 | E10: 1 | F10: 1 | G10: 1 | H10: 1 | I10: 1 | J10: 1 | K10: 1 | L10: 1 | M10: 1 | N10: [객관] 1.0 — 비지배지분 0 (연결 전액 지배주주 귀속).
A11: 발행주식수 | B11: shares | C11: 백만주 | D11: 42.1917 | E11: 42.1917 | F11: 42.1917 | G11: 42.1917 | H11: 42.1917 | I11: 42.1917 | J11: 42.1917 | K11: 42.1917 | L11: 42.1917 | M11: 42.1917 | N11: [객관] 42.19백만주 (2026-09 현재, 하나증권·WISEreport 일치). 2025말 40.93백만주에서 CB 전환으로 증가 — 전환 잔량이 남아 있어 추가 희석 여지.
A12: DPS 실적 | B12: dps_a | C12: 원 | D12: 0 | E12: 0 | F12: 0 | G12: 0 | H12: 0 | I12: 0 | J12: 0 | K12: 0 | L12: 0 | M12: 0 | N12: [객관] 전 연도 0 — 배당 이력 없음(누적 결손).
A13: 배당성향 | B13: payout | C13: % | D13: 0 | E13: 0 | F13: 0 | G13: 0 | H13: 0 | I13: 0 | J13: 0 | K13: 0 | L13: 0 | M13: 0 | N13: [주관] 0. 결손 해소 전 배당 가능성 없음.
A14: FILTER 실적 | B14: fil_actual | C14: 억원 | D14: 1107.9802 | E14: 1365.9338 | F14: 634.41288 | G14: 351.95147 | H14: 572.82625 | I14: 0 | J14: 0 | K14: 0 | L14: 0 | M14: 0 | N14: [객관] 사업보고서 II-4 매출실적(연결). 합계 정합을 위해 IS 매출에서 역산 — 공시 표와 최대 0.007억 차이(표가 백만원 반올림).
A15: FILTER 성장률 | B15: fil_g | C15: % | D15: 0 | E15: 0 | F15: 0 | G15: 0 | H15: 0 | I15: 0.0213 | J15: 0.5 | K15: 0.45 | L15: 0.22 | M15: 0.1 | N15: [주관] 2026 +2.1%(상반기 확정이 전사 −10.9%라 크게 못 늘림), 2027 +50% · 2028 +45% — 미국 어퍼C밴드 경매(2027.4)의 부분 수혜를 하반기부터 반영. 검증 안 된 것: 삼성전자의 버라이즌 벤더 선정, 그 안의 KMW 채택. 수주 공시가 없어 하나증권처럼 2027 +259%(전사)를 Base에 둘 근거가 없다 — 그 경로는 Bull.
A16: ANTENNA 실적 | B16: ant_actual | C16: 억원 | D16: 165.43 | E16: 102.23 | F16: 131.59 | G16: 233.83 | H16: 189.74 | I16: 0 | J16: 0 | K16: 0 | L16: 0 | M16: 0 | N16: [객관] 사업보고서 II-4 매출실적(연결, 백만원 공시).
A17: ANTENNA 성장률 | B17: ant_g | C17: % | D17: 0 | E17: 0 | F17: 0 | G17: 0 | H17: 0 | I17: -0.0777 | J17: 0.4 | K17: 0.38 | L17: 0.2 | M17: 0.1 | N17: [주관] 2026 −7.8%(상반기 역성장 반영), 2027~2028 +40%·+38% — 경매 후 기지국 신설 물량의 부분 수혜.
A18: SYSTEM 실적 | B18: sys_actual | C18: 억원 | D18: 631.9 | E18: 152.44 | F18: 52.62 | G18: 134.79 | H18: 21.45 | I18: 0 | J18: 0 | K18: 0 | L18: 0 | M18: 0 | N18: [객관] 사업보고서 II-4 매출실적(연결). 2021부터 RTS 제품을 SYSTEM류로 분류(FY2022 보고서 주석) — 2021은 그 기준.
... A30: 순차입금 | B30: net_debt | C30: 억원 | D30: -1196.45 | E30: -712.94 | F30: -331.2 | G30: 70.4 | H30: 231.5 | I30: 231.5 | J30: 231.5 | K30: 231.5 | L30: 231.5 | M30: 231.5 | N30: [객관 실적 / 추정 구간 고정] 단기+장기차입금+전환사채 − 현금성자산·단기금융. **순현금 1,196억(2021) → 순차입 232억(2025)** — 5년 적자가 1,400억을 태웠고 유상증자·CB(2023~2025)로 메웠다. 추정 구간 2025년 고정은 이 종목에서는 보수가 아니라 낙관 쪽이다 — Base 경로로도 2028년까지 적자라 실제로는 추가 조달(희석) 가능성이 높다. 하나증권 "순금융부채"(2025 368억)는 리스·기타 금융부채를 포함해 범위가 다르다.

Sheet Model
A1: 케이엠더블유 투자심사 모델
A2: 단위 억원 · 실적 5개년 + 추정 5개년
D3: 실적 | E3: 실적 | F3: 실적 | G3: 실적 | H3: 실적 | I3: 추정 | J3: 추정 | K3: 추정 | L3: 추정 | M3: 추정
A4: 계정 | B4: 노드 id | C4: 단위 | D4: 2021A | E4: 2022A | F4: 2023A | G4: 2024A | H4: 2025A | I4: 2026E | J4: 2027E | K4: 2028E | L4: 2029E | M4: 2030E
A5: 적정 시가총액 | B5: root | C5: 억원 | D5: =(D6-D46) | E5: =(E6-E46) | F5: =(F6-F46) | G5: =(G6-G46) | H5: =(H6-H46) | I5: =(I6-I46) | J5: =(J6-J46) | K5: =(K6-K46) | ... M5: =(M6-M46)
A6: 사업가치 (EV) | B6: ev_value | C6: 억원 | D6: =(D8*D7) | E6: =(E8*E7) | F6: =(F8*F7) | G6: =(G8*G7) | H6: =(H8*H7) | I6: =(I8*I7) | J6: =(J8*J7) | K6: =(K8*K7) | ... M6: =(M8*M7)
A7: 목표 EV/EBITDA | B7: target_ev_ebitda | C7: 배 | D7: 8 | E7: 8 | F7: 8 | G7: 8 | H7: 8 | I7: 8 | J7: 8 | K7: 8 | L7: 8 | M7: 8
A8: EBITDA | B8: ebitda | C8: 억원 | D8: =(D9+D43) | E8: =(E9+E43) | F8: =(F9+F43) | G8: =(G9+G43) | H8: =(H9+H43) | I8: =(I9+I43) | J8: =(J9+J43) | K8: =(K9+K43) | ... M8: =(M9+M43)
A9: 영업이익 | B9: op_profit | C9: 억원 | D9: =(((D21-D34)-D37)-D40) | E9: =(((E21-E34)-E37)-E40) | F9: =(((F21-F34)-F37)-F40) | G9: =(((G21-G34)-G37)-G40) | H9: =(((H21-H34)-H37)-H40) | I9: =(((I21-I34)-I37)-I40) | J9: =(((J21-J34)-J37)-J40) | K9: =(((K21-K34)-K37)-K40) | ... M9: =(((M21-M34)-M37)-M40)
A10: 지배주주 순이익 (참고) | B10: net_income | C10: 억원 | D10: =IF((D11>0),D12,(((D9+D13)*(1-D14))*D15)) | E10: =IF((E11>0),E12,(((E9+E13)*(1-E14))*E15)) | F10: =IF((F11>0),F12,(((F9+F13)*(1-F14))*F15)) | G10: =IF((G11>0),G12,(((G9+G13)*(1-G14))*G15)) | H10: =IF((H11>0),H12,(((H9+H13)*(1-H14))*H15)) | I10: =IF((I11>0),I12,(((I9+I13)*(1-I14))*I15)) | J10: =IF((J11>0),J12,(((J9+J13)*(1-J14))*J15)) | K10: =IF((K11>0),K12,(((K9+K13)*(1-K14))*K15)) | ... M10: =IF((M11>0),M12,(((M9+M13)*(1-M14))*M15))
A11: 순이익 실적 마스크 | B11: ni_hist | D11: 1 | E11: 1 | F11: 1 | G11: 1 | H11: 1 | I11: 0 | J11: 0 | K11: 0 | L11: 0 | M11: 0
A12: 순이익 실적 | B12: ni_actual | C12: 억원 | D12: -37.293762 | E12: -266.86463 | F12: -652.86676 | G12: -386.04141 | H12: -270.33047 | I12: 0 | J12: 0 | K12: 0 | L12: 0 | M12: 0
A13: 영업외손익 | B13: nonop | C13: 억원 | D13: 0 | E13: 0 | F13: 0 | G13: 0 | H13: 0 | I13: -85 | J13: -40 | K13: -25 | L13: -15 | M13: -10
A14: 실효세율 | B14: tax_rate | C14: % | D14: 0.08 | E14: 0.08 | F14: 0.08 | G14: 0.08 | H14: 0.08 | I14: 0.08 | J14: 0.08 | K14: 0.08 | L14: 0.08 | M14: 0.08
A15: 지배지분비율 | B15: ctrl_ratio | C15: % | D15: 1 | E15: 1 | F15: 1 | G15: 1 | H15: 1 | I15: 1 | J15: 1 | K15: 1 | L15: 1 | M15: 1
A16: EPS (참고) | B16: eps | C16: 원 | D16: =((D10/D17)*100) | E16: =((E10/E17)*100) | F16: =((F10/F17)*100) | G16: =((G10/G17)*100) | H16: =((H10/H17)*100) | I16: =((I10/I17)*100) | J16: =((J10/J17)*100) | K16: =((K10/K17)*100) | ... M16: =((M10/M17)*100)
A17: 발행주식수 | B17: shares | C17: 백만주 | D17: 42.1917 | E17: 42.1917 | F17: 42.1917 | G17: 42.1917 | H17: 42.1917 | I17: 42.1917 | J17: 42.1917 | K17: 42.1917 | L17: 42.1917 | M17: 42.1917
A18: DPS (참고) | B18: dps | C18: 원 | D18: =IF((D11>0),D19,(D16*D20)) | E18: =IF((E11>0),E19,(E16*E20)) | F18: =IF((F11>0),F19,(F16*F20)) | G18: =IF((G11>0),G19,(G16*G20)) | H18: =IF((H11>0),H19,(H16*H20)) | I18: =IF((I11>0),I19,(I16*I20)) | J18: =IF((J11>0),J19,(J16*J20)) | K18: =IF((K11>0),K19,(K16*K20)) | ... M18: =IF((M11>0),M19,(M16*M20))
A19: DPS 실적 | B19: dps_a | C19: 원 | D19: 0 | E19: 0 | F19: 0 | G19: 0 | H19: 0 | I19: 0 | J19: 0 | K19: 0 | L19: 0 | M19: 0
A20: 배당성향 | B20: payout | C20: % | D20: 0 | E20: 0 | F20: 0 | G20: 0 | H20: 0 | I20: 0 | J20: 0 | K20: 0 | L20: 0 | M20: 0
A21: 총매출 | B21: total_revenue | C21: 억원 | D21: =(((D22+D25)+D28)+D31) | E21: =(((E22+E25)+E28)+E31) | F21: =(((F22+F25)+F28)+F31) | G21: =(((G22+G25)+G28)+G31) | H21: =(((H22+H25)+H28)+H31) | I21: =(((I22+I25)+I28)+I31) | J21: =(((J22+J25)+J28)+J31) | K21: =(((K22+K25)+K28)+K31) | ... M21: =(((M22+M25)+M28)+M31)
A22: RF FILTER류·기타 | B22: rf_filter | C22: 억원 | D22: =IF((D23>0),D23,(0*(1+D24))) | E22: =IF((E23>0),E23,(D22*(1+E24))) | F22: =IF((F23>0),F23,(E22*(1+F24))) | G22: =IF((G23>0),G23,(F22*(1+G24))) | H22: =IF((H23>0),H23,(G22*(1+H24))) | I22: =IF((I23>0),I23,(H22*(1+I24))) | J22: =IF((J23>0),J23,(I22*(1+J24))) | K22: =IF((K23>0),K23,(J22*(1+K24))) | L22: =IF((L23>0),L23,(K22*(1+L24))) | M22: =IF((M23>0),M23,(L22*(1+M24)))
A23: FILTER 실적 | B23: fil_actual | C23: 억원 | D23: 1107.9802 | E23: 1365.9338 | F23: 634.41288 | G23: 351.95147 | H23: 572.82625 | I23: 0 | J23: 0 | K23: 0 | L23: 0 | M23: 0
A24: FILTER 성장률 | B24: fil_g | C24: % | D24: 0 | E24: 0 | F24: 0 | G24: 0 | H24: 0 | I24: 0.0213 | J24: 0.5 | K24: 0.45 | L24: 0.22 | M24: 0.1
A25: RF ANTENNA류 | B25: rf_antenna | C25: 억원 | D25: =IF((D26>0),D26,(0*(1+D27))) | E25: =IF((E26>0),E26,(D25*(1+E27))) | F25: =IF((F26>0),F26,(E25*(1+F27))) | G25: =IF((G26>0),G26,(F25*(1+G27))) | H25: =IF((H26>0),H26,(G25*(1+H27))) | I25: =IF((I26>0),I26,(H25*(1+I27))) | J25: =IF((J26>0),J26,(I25*(1+J27))) | K25: =IF((K26>0),K26,(J25*(1+K27))) | L25: =IF((L26>0),L26,(K25*(1+L27))) | M25: =IF((M26>0),M26,(L25*(1+M27)))
A26: ANTENNA 실적 | B26: ant_actual | C26: 억원 | D26: 165.43 | E26: 102.23 | F26: 131.59 | G26: 233.83 | H26: 189.74 | I26: 0 | J26: 0 | K26: 0 | L26: 0 | M26: 0
A27: ANTENNA 성장률 | B27: ant_g | C27: % | D27: 0 | E27: 0 | F27: 0 | G27: 0 | H27: 0 | I27: -0.0777 | J27: 0.4 | K27: 0.38 | L27: 0.2 | M27: 0.1
A28: RF SYSTEM류 | B28: rf_system | C28: 억원 | D28: =IF((D29>0),D29,(0*(1+D30))) | E28: =IF((E29>0),E29,(D28*(1+E30))) | F28: =IF((F29>0),F29,(E28*(1+F30))) | G28: =IF((G29>0),G29,(F28*(1+G30))) | H28: =IF((H29>0),H29,(G28*(1+H30))) | I28: =IF((I29>0),I29,(H28*(1+I30))) | J28: =IF((J29>0),J29,(I28*(1+J30))) | K28: =IF((K29>0),K29,(J28*(1+K30))) | L28: =IF((L29>0),L29,(K28*(1+L30))) | M28: =IF((M29>0),M29,(L28*(1+M30)))
A29: SYSTEM 실적 | B29: sys_actual | C29: 억원 | D29: 631.9 | E29: 152.44 | F29: 52.62 | G29: 134.79 | H29: 21.45 | I29: 0 | J29: 0 | K29: 0 | L29: 0 | M29: 0
A30: SYSTEM 성장률 | B30: sys_g | C30: % | D30: 0 | E30: 0 | F30: 0 | G30: 0 | H30: 0 | I30: 0.1655 | J30: 1.8 | K30: 1.2 | L30: 0.35 | M30: 0.15
A31: LED | B31: led | C31: 억원 | D31: =IF((D32>0),D32,(0*(1+D33))) | E31: =IF((E32>0),E32,(D31*(1+E33))) | F31: =IF((F32>0),F32,(E31*(1+F33))) | G31: =IF((G32>0),G32,(F31*(1+G33))) | H31: =IF((H32>0),H32,(G31*(1+H33))) | I31: =IF((I32>0),I32,(H31*(1+I33))) | J31: =IF((J32>0),J32,(I31*(1+J33))) | K31: =IF((K32>0),K32,(J31*(1+K33))) | L31: =IF((L32>0),L32,(K31*(1+L33))) | M31: =IF((M32>0),M32,(L31*(1+M33)))
A32: LED 실적 | B32: led_actual | C32: 억원 | D32: 146.28 | E32: 174.02 | F32: 182.06 | G32: 153 | H32: 191.17 | I32: 0 | J32: 0 | K32: 0 | L32: 0 | M32: 0
A33: LED 성장률 | B33: led_g | C33: % | D33: 0 | E33: 0 | F33: 0 | G33: 0 | H33: 0 | I33: -0.0846 | J33: 0.05 | K33: 0.04 | L33: 0.03 | M33: 0.03
A34: 매출원가 | B34: cogs | C34: 억원 | D34: =IF((D35>0),D35,(D21*D36)) | E34: =IF((E35>0),E35,(E21*E36)) | F34: =IF((F35>0),F35,(F21*F36)) | G34: =IF((G35>0),G35,(G21*G36)) | H34: =IF((H35>0),H35,(H21*H36)) | I34: =IF((I35>0),I35,(I21*I36)) | J34: =IF((J35>0),J35,(J21*J36)) | K34: =IF((K35>0),K35,(K21*K36)) | ... M34: =IF((M35>0),M35,(M21*M36))
A35: 매출원가 실적 | B35: cogs_actual | C35: 억원 | D35: 1550.0633 | E35: 1466.4148 | F35: 929.32103 | G35: 754.98515 | H35: 845.16037 | I35: 0 | J35: 0 | K35: 0 | L35: 0 | M35: 0
A36: 매출원가율 | B36: cogs_ratio | C36: % | D36: 0 | E36: 0 | F36: 0 | G36: 0 | H36: 0 | I36: 0.865 | J36: 0.825 | K36: 0.775 | L36: 0.75 | M36: 0.735
A37: 판매비와관리비 | B37: sga_cost | C37: 억원 | D37: =IF((D38>0),D38,(0*(1+D39))) | E37: =IF((E38>0),E38,(D37*(1+E39))) | F37: =IF((F38>0),F38,(E37*(1+F39))) | G37: =IF((G38>0),G38,(F37*(1+G39))) | H37: =IF((H38>0),H38,(G37*(1+H39))) | I37: =IF((I38>0),I38,(H37*(1+I39))) | J37: =IF((J38>0),J38,(I37*(1+J39))) | K37: =IF((K38>0),K38,(J37*(1+K39))) | L37: =IF((L38>0),L38,(K37*(1+L39))) | M37: =IF((M38>0),M38,(L37*(1+M39)))
A38: 판관비 실적 | B38: sga_actual | C38: 억원 | D38: 368.29501 | E38: 359.35579 | F38: 322.71133 | G38: 290.65846 | H38: 253.92503 | I38: 0 | J38: 0 | K38: 0 | L38: 0 | M38: 0
A39: 판관비 증가율 | B39: sga_g | C39: % | D39: 0 | E39: 0 | F39: 0 | G39: 0 | H39: 0 | I39: -0.015 | J39: 0.088 | K39: 0.103 | L39: 0.083 | M39: 0.062
A40: 경상연구개발비 | B40: rnd_cost | C40: 억원 | D40: =IF((D41>0),D41,(0*(1+D42))) | E40: =IF((E41>0),E41,(D40*(1+E42))) | F40: =IF((F41>0),F41,(E40*(1+F42))) | G40: =IF((G41>0),G41,(F40*(1+G42))) | H40: =IF((H41>0),H41,(G40*(1+H42))) | I40: =IF((I41>0),I41,(H40*(1+I42))) | J40: =IF((J41>0),J41,(I40*(1+J42))) | K40: =IF((K41>0),K41,(J40*(1+K42))) | L40: =IF((L41>0),L41,(K40*(1+L42))) | M40: =IF((M41>0),M41,(L40*(1+M42)))
...

Sheet Formula Audit
A1: 수식 감사
A2: 모델 원식 ↔ Excel 셀 수식 대조. 변환은 엔진의 astToExcel이 담당한다.
A4: 노드 id | B4: 계정 | C4: 행 | D4: 모델 원식 | E4: 첫 추정연도 셀 수식
A5: root | B5: 적정 시가총액 | C5: 5 | D5: ev_value - net_debt | E5: '=(I6-I46)
A6: ev_value | B6: 사업가치 (EV) | C6: 6 | D6: ebitda * target_ev_ebitda | E6: '=(I8*I7)
A7: ebitda | B7: EBITDA | C7: 8 | D7: op_profit + dep_total | E7: '=(I9+I43)
A8: op_profit | B8: 영업이익 | C8: 9 | D8: total_revenue - cogs - sga_cost - rnd_cost | E8: '=(((I21-I34)-I37)-I40)
A9: net_income | B9: 지배주주 순이익 (참고) | C9: 10 | D9: IF(ni_hist > 0, ni_actual, (op_profit + nonop) * (1 - tax_rate) * ctrl_ratio) | E9: '=IF((I11>0),I12,(((I9+I13)*(1-I14))*I15))
A10: eps | B10: EPS (참고) | C10: 16 | D10: net_income / shares * 100 | E10: '=((I10/I17)*100)
A11: dps | B11: DPS (참고) | C11: 18 | D11: IF(ni_hist > 0, dps_a, eps * payout) | E11: '=IF((I11>0),I19,(I16*I20))
A12: total_revenue | B12: 총매출 | C12: 21 | D12: rf_filter + rf_antenna + rf_system + led | E12: '=(((I22+I25)+I28)+I31)
A13: rf_filter | B13: RF FILTER류·기타 | C13: 22 | D13: IF(fil_actual > 0, fil_actual, PREV(rf_filter) * (1 + fil_g)) | E13: '=IF((I23>0),I23,(H22*(1+I24)))
A14: rf_antenna | B14: RF ANTENNA류 | C14: 25 | D14: IF(ant_actual > 0, ant_actual, PREV(rf_antenna) * (1 + ant_g)) | E14: '=IF((I26>0),I26,(H25*(1+I27)))
A15: rf_system | B15: RF SYSTEM류 | C15: 28 | D15: IF(sys_actual > 0, sys_actual, PREV(rf_system) * (1 + sys_g)) | E15: '=IF((I29>0),I29,(H28*(1+I30)))
A16: led | B16: LED | C16: 31 | D16: IF(led_actual > 0, led_actual, PREV(led) * (1 + led_g)) | E16: '=IF((I32>0),I32,(H31*(1+I33)))
... A20: dep_total | B20: 유·무형 감가상각비 | C20: 43 | D20: IF(dep_actual > 0, dep_actual, PREV(dep_total) * (1 + dep_g)) | E20: '=IF((I44>0),I44,(H43*(1+I45)))

Sheet Structure
A1: 트리 구조
A3: 노드 id | B3: 계정 | C3: 깊이 | D3: 유형 | E3: 합계형 | F3: 행 | G3: 단위
A4: root | B4: 적정 시가총액 | C4: 0 | D4: computed | F4: 5 | G4: 억원
A5: ev_value | B5: 사업가치 (EV) | C5: 1 | D5: computed | F5: 6 | G5: 억원
A6: target_ev_ebitda | B6: 목표 EV/EBITDA | C6: 2 | D6: input | F6: 7 | G6: 배
A7: ebitda | B7: EBITDA | C7: 2 | D7: computed | E7: Y | F7: 8 | G7: 억원
A8: op_profit | B8: 영업이익 | C8: 3 | D8: computed | F8: 9 | G8: 억원
A9: net_income | B9: 지배주주 순이익 (참고) | C9: 4 | D9: computed | F9: 10 | G9: 억원
A10: ni_hist | B10: 순이익 실적 마스크 | C10: 5 | D10: input | F10: 11
A11: ni_actual | B11: 순이익 실적 | C11: 5 | D11: input | F11: 12 | G11: 억원
A12: nonop | B12: 영업외손익 | C12: 5 | D12: input | F12: 13 | G12: 억원
A13: tax_rate | B13: 실효세율 | C13: 5 | D13: input | F13: 14 | G13: %
A14: ctrl_ratio | B14: 지배지분비율 | C14: 5 | D14: input | F14: 15 | G14: %
A15: eps | B15: EPS (참고) | C15: 5 | D15: computed | F15: 16 | G15: 원
A16: shares | B16: 발행주식수 | C16: 6 | D16: input | F16: 17 | G16: 백만주
A17: dps | B17: DPS (참고) | C17: 5 | D17: computed | F17: 18 | G17: 원
A18: dps_a | B18: DPS 실적 | C18: 6 | D18: input | F18: 19 | G18: 원
A19: payout | B19: 배당성향 | C19: 6 | D19: input | F19: 20 | G19: %
A20: total_revenue | B20: 총매출 | C20: 4 | D20: computed | E20: Y | F20: 21 | G20: 억원
A21: rf_filter | B21: RF FILTER류·기타 | C21: 5 | D21: computed | F21: 22 | G21: 억원
A22: fil_actual | B22: FILTER 실적 | C22: 6 | D22: input | F22: 23 | G22: 억원
A23: fil_g | B23: FILTER 성장률 | C23: 6 | D23: input | F23: 24 | G23: %
A24: rf_antenna | B24: RF ANTENNA류 | C24: 5 | D24: computed | F24: 25 | G24: 억원
A25: ant_actual | B25: ANTENNA 실적 | C25: 6 | D25: input | F25: 26 | G25: 억원
A26: ant_g | B26: ANTENNA 성장률 | C26: 6 | D26: input | F26: 27 | G26: %
A27: rf_system | B27: RF SYSTEM류 | C27: 5 | D27: computed | F27: 28 | G27: 억원
A28: sys_actual | B28: SYSTEM 실적 | C28: 6 | D28: input | F28: 29 | G28: 억원
A29: sys_g | B29: SYSTEM 성장률 | C29: 6 | D29: input | F29: 30 | G29: %
A30: led | B30: LED | C30: 5 | D30: computed | F30: 31 | G30: 억원
A31: led_actual | B31: LED 실적 | C31: 6 | D31: input | F31: 32 | G31: 억원
A32: led_g | B32: LED 성장률 | C32: 6 | D32: input | F32: 33 | G32: %
... A45: net_debt | B45: 순차입금 | C45: 1 | D45: input | F45: 46 | G45: 억원

Sheet Checks
A1: 검증
A2: 합계형 노드의 부모값과 자식 합의 차이. 전 칸이 0이어야 한다.
D3: 실적 | E3: 실적 | F3: 실적 | G3: 실적 | H3: 실적 | I3: 추정 | J3: 추정 | K3: 추정 | L3: 추정 | M3: 추정
A4: 계정 | B4: 검사 | D4: 2021A | E4: 2022A | F4: 2023A | G4: 2024A | H4: 2025A | I4: 2026E | J4: 2027E | K4: 2028E | L4: 2029E | M4: 2030E
A5: EBITDA | B5: 부모 − 자식합 | D5: =ROUND(Model!D8-(Model!D9+Model!D43),6) | E5: =ROUND(Model!E8-(Model!E9+Model!E43),6) | F5: =ROUND(Model!F8-(Model!F9+Model!F43),6) | G5: =ROUND(Model!G8-(Model!G9+Model!G43),6) | H5: =ROUND(Model!H8-(Model!H9+Model!H43),6) | I5: =ROUND(Model!I8-(Model!I9+Model!I43),6) | J5: =ROUND(Model!J8-(Model!J9+Model!J43),6) | K5: =ROUND(Model!K8-(Model!K9+Model!K43),6) | ... M5: =ROUND(Model!M8-(Model!M9+Model!M43),6)
A6: 총매출 | B6: 부모 − 자식합 | D6: =ROUND(Model!D21-(Model!D22+Model!D25+Model!D28+Model!D31),6) | E6: =ROUND(Model!E21-(Model!E22+Model!E25+Model!E28+Model!E31),6) | F6: =ROUND(Model!F21-(Model!F22+Model!F25+Model!F28+Model!F31),6) | G6: =ROUND(Model!G21-(Model!G22+Model!G25+Model!G28+Model!G31),6) | H6: =ROUND(Model!H21-(Model!H22+Model!H25+Model!H28+Model!H31),6) | I6: =ROUND(Model!I21-(Model!I22+Model!I25+Model!I28+Model!I31),6) | J6: =ROUND(Model!J21-(Model!J22+Model!J25+Model!J28+Model!J31),6) | K6: =ROUND(Model!K21-(Model!K22+Model!K25+Model!K28+Model!K31),6) | ... M6: =ROUND(Model!M21-(Model!M22+Model!M25+Model!M28+Model!M31),6)
A8: 합계형 노드 수 | B8: 2

Sheet Metadata
A1: 빌드 정보
A3: 소스 | B3: model.html
A4: 소스 해시 (sha256 앞 16자리) | B4: cb64f5beda7cb937
A5: 빌더 | B5: tools/build_excel.py
A6: 수식 변환 | B6: 엔진 astToExcel (JS) — 파이썬은 배치만 한다
A7: 노드 수 | B7: 42
A8: 입력 노드 수 | B8: 26
A9: 연도 수 | B9: 10
A10: HIST_N | B10: 5
A11: 모델 id | B11: kmw_spectrum_cycle
