Workbook

Sheet Index
A1: KT&G 투자심사 모델
A2: tools/build_excel.py가 model.html에서 생성. 직접 고치지 말 것 — 다음 빌드에 덮인다.
A4: 시트 | B4: 내용
A5: Index | B5: 이 시트
A6: Control | B6: 모델 개요·전역 설정
A7: Assumptions | B7: 가정변수 일람과 근거
A8: Model | B8: 계정 트리 × 연도. 수식이 살아있는 본체
A9: Formula Audit | B9: 모델 원식 ↔ 셀 수식 대조
A10: Structure | B10: 트리 구조·깊이·행 배치
A11: Checks | B11: 부모 = 자식 합 정합 검증
A12: Metadata | B12: 빌드 정보
A14: 셀 색 규약
A15: 파랑 글자 | B15: 하드코딩 입력값 — 여기만 고친다
A16: 검정 글자 | B16: 수식
A17: 회색 배경 | B17: 실적(Historical) 구간 — 공시 확정값

Sheet Control
A1: 컨트롤
A2: 가정을 바꾸려면 Assumptions 시트가 아니라 Model 시트의 파랑 셀을 고친다. Model이 계산의 단일 출처다.
A4: 모델 | B4: KT&G 투자심사 모델
A5: 통화 단위 | B5: 억원
A6: 범위 | B6: 매출 → 영업이익 → DCF
A7: 실적 연도 수 (HIST_N) | B7: 4
A8: 추정 연도 수 | B8: 5
A9: 첫 연도 | B9: 2022
A10: 마지막 연도 | B10: 2030

Sheet Assumptions
A1: 가정변수 일람
A2: 파랑 = 하드코딩 입력값. 근거 열의 대괄호 태그가 객관/주관 구분이다.
D3: 실적 | E3: 실적 | F3: 실적 | G3: 실적 | H3: 추정 | I3: 추정 | J3: 추정 | K3: 추정 | L3: 추정
A4: 계정 | B4: 노드 id | C4: 단위 | D4: 2022A | E4: 2023A | F4: 2024A | G4: 2025A | H4: 2026E | I4: 2027E | J4: 2028E | K4: 2029E | L4: 2030E | M4: 근거
A5: 법인세율 | B5: tax_rate | C5: % | D5: 0.24 | E5: 0.24 | F5: 0.24 | G5: 0.24 | H5: 0.24 | I5: 0.24 | J5: 0.24 | K5: 0.24 | L5: 0.24 | M5: [주관] 실효세율 24%로 고정했다. 국내 법인세 최고세율(지방세 포함 약 26%)에 해외 자회사 세율과 세액공제를 반영해 낮춘 값이다. 정확한 실효세율은 연도마다 다르나 DCF 결과에 대한 민감도가 낮아(민감도 뷰 참조) 단일값으로 둔다.
A6: 순이익 실적 마스크 | B6: ni_hist | D6: 1 | E6: 1 | F6: 1 | G6: 1 | H6: 0 | I6: 0 | J6: 0 | K6: 0 | L6: 0 | M6: [객관] 실적 연도 표시(1). 순이익은 적자 연도가 있어 "실적 > 0" 관용구를 쓸 수 없다 — LGD·삼성전자 DS에서 확립한 hist 마스크 패턴.
A7: 순이익 실적 | B7: ni_actual | C7: 억원 | D7: 10157.85 | E7: 9026.62 | F7: 11657.27 | G7: 10900.72 | H7: 0 | I7: 0 | J7: 0 | K7: 0 | L7: 0 | M7: [객관] 연결 지배주주 순이익 확정값 (사업보고서 연결포괄손익계산서).
A8: 영업외손익 | B8: nonop | C8: 억원 | D8: 1618.19 | E8: 810.82 | F8: 3770.25 | G8: 1115.91 | H8: 1200 | I8: 1200 | J8: 1200 | K8: 1200 | L8: 1200 | M8: [주관 추정 · 실적은 공시값] 영업외손익 = 세전이익 − 영업이익(연결). 실적 +1,618/+811/+3,770/+1,116억 — 금융수익·부동산 관련. 2024 급증은 경상 수준이 아니라고 보고 **+1,200억 고정**.
A9: 지배지분 비율 | B9: ctrl_ratio | C9: % | D9: 0 | E9: 0 | F9: 0 | G9: 0 | H9: 0.99 | I9: 0.99 | J9: 0.99 | K9: 0.99 | L9: 0.99 | M9: [주관] 지배지분 비율. 실적 98~101%(비지배 손익이 음수인 해 존재) — 99% 고정.
A10: 상장주식수 | B10: shares | C10: 백만주 | D10: 103.81046 | E10: 103.81046 | F10: 103.81046 | G10: 103.81046 | H10: 103.81046 | I10: 103.81046 | J10: 103.81046 | K10: 103.81046 | L10: 103.81046 | M10: [객관] 상장 보통주 103,810,456주 고정. 자사주 소각으로 매년 줄어온 주식수의 현재값 — **소각 지속 시 EPS에 추가 상방**이 있으나 미모델.
A11: DPS 실적 | B11: dps_a | C11: 원 | D11: 5000 | E11: 5200 | F11: 5400 | G11: 6000 | H11: 0 | I11: 0 | J11: 0 | K11: 0 | L11: 0 | M11: [객관] 주당 현금배당. 실적 5,000/5,200/5,400/6,000원 — 4년 연속 증배.
A12: 배당성향 | B12: payout | C12: % | D12: 0 | E12: 0 | F12: 0 | G12: 0 | H12: 0.57 | I12: 0.57 | J12: 0.57 | K12: 0.57 | L12: 0.57 | M12: [주관] 배당성향. 실적 57.2/65.4/50.5/57.6% — **57% 유지** 가정. 자사주 소각을 더한 총주주환원은 이보다 높다.
A13: 감가상각비 실적 | B13: dep_actual | C13: 억원 | D13: 2341 | E13: 2515 | F13: 2626 | G13: 3043 | H13: 0 | I13: 0 | J13: 0 | K13: 0 | L13: 0 | M13: [객관] DART 연결 영업부문 주석. 추정 구간은 0으로 두고 증가율로 굴린다.
A14: 감가상각 증가율 | B14: dep_g | C14: % | D14: 0 | E14: 0 | F14: 0 | G14: 0 | H14: 0.09 | I14: 0.07 | J14: 0.05 | K14: 0.04 | L14: 0.03 | M14: [주관] 실적 4년 연평균 +9.1%. CAPEX가 2024년에 정점을 찍고 내려오는 것을 반영해 9%에서 3%로 낮췄다. CAPEX 비율 가정과 방향이 일치해야 한다 — 둘이 어긋나면 감가상각이 투자와 무관하게 움직이는 모델이 된다.
A15: 기타비용 실적 | B15: other_actual | C15: 억원 | D15: 43496 | E15: 44438 | F15: 44574 | G15: 49317 | H15: 0 | I15: 0 | J15: 0 | K15: 0 | L15: 0 | M15: [객관] 매출 − 영업이익 − 감가상각비로 유도한 확정값.
A16: 기타비용률 | B16: other_ratio | C16: % | D16: 0 | E16: 0 | F16: 0 | G16: 0 | H16: 0.75 | I16: 0.749 | J16: 0.748 | K16: 0.747 | L16: 0.746 | M16: [주관] 매출 대비 기타비용. 실적 74.3% → 75.8% → 75.4% → 75.0%로 4년 내내 1.5%p 범위 안이다. 이 회사에서 가장 예측 가능한 숫자다. 2025년 수준에서 연 0.1%p씩만 개선한다고 봤다 — 해외 매출 비중 상승에 따른 믹스 개선을 최소한으로만 반영한 것이고, 근거가 약해 크게 움직이지 않았다.
A17: 담배 실적 | B17: tob_actual | C17: 억원 | D17: 35738 | E17: 36123 | F17: 39056 | G17: 43672 | H17: 0 | I17: 0 | J17: 0 | K17: 0 | L17: 0 | M17: [객관] DART 연결 영업부문 주석 외부고객수익.
A18: 담배 성장률 | B18: tob_g | C18: % | D18: 0 | E18: 0 | F18: 0 | G18: 0 | H18: 0.07 | I18: 0.06 | J18: 0.05 | K18: 0.04 | L18: 0.03 | M18: [주관] 국내는 물량 감소·단가 상승으로 대체로 보합이고, 성장은 전부 해외에서 온다. 최근 2년 +8.1%, +11.8%를 그대로 연장하지 않고 7%에서 3%로 체감시켰다 — 해외 진출 초기의 높은 성장률은 기저가 커지면 유지되지 않는다.
... A26: CAPEX 비율 | B26: capex_ratio | C26: % | D26: 0 | E26: 0 | F26: 0 | G26: 0 | H26: 0.095 | I26: 0.09 | J26: 0.085 | K26: 0.08 | L26: 0.075 | M26: [주관] 매출 대비 CAPEX. 실적 4.8% → 8.8% → 13.5% → 10.3%로 최근 3년이 투자 확대 국면이었다. 해외 궐련 생산능력 확충이 일단락된다고 보고 9.5%에서 7.5%로 완만히 낮췄다. 감가상각비(3.0%)보다 여전히 높게 둔 것은 성장 투자가 이어진다는 뜻이다.
A27: 실적 구간 표시 | B27: df_hist | D27: 1 | E27: 1 | F27: 1 | G27: 1 | H27: 0 | I27: 0 | J27: 0 | K27: 0 | L27: 0 | M27: [객관] 실적 구간이면 1, 추정 구간이면 0. 할인을 언제부터 시작할지 정하는 마스크다. 엔진에 연도 인덱스 함수가 없어 데이터로 표현한다.
A28: WACC | B28: wacc | C28: % | D28: 0.08 | E28: 0.08 | F28: 0.08 | G28: 0.08 | H28: 0.08 | I28: 0.08 | J28: 0.08 | K28: 0.08 | L28: 0.08 | M28: [주관] 가중평균자본비용 8.0%. 무위험수익률 3% + 베타 0.6 × 시장위험프리미엄 7% ≈ 7.2%의 자기자본비용에, 순차입금 비중이 낮아 사실상 자기자본비용이 그대로 WACC가 된다. 여유를 둬 8%로 올렸다. 이 모델에서 목표배수에 해당하는 가장 강력한 단일 가정이다 — 민감도 뷰에서 확인한다.
A29: 영구성장률 | B29: tv_growth | C29: % | D29: 0.01 | E29: 0.01 | F29: 0.01 | G29: 0.01 | H29: 0.01 | I29: 0.01 | J29: 0.01 | K29: 0.01 | L29: 0.01 | M29: [주관] 1.0%. 국내 궐련 시장은 물량이 줄고 단가가 오르는 구조라 장기 성장률을 물가상승률 아래로 둔다. 해외 궐련·NGP가 이를 상쇄한다는 것이 상방 논리이나 Base에는 반영하지 않았다.
A30: 순차입금 | B30: net_debt | C30: 억원 | D30: -12455 | E30: -4964 | F30: 3375 | G30: 8556 | H30: 8556 | I30: 8556 | J30: 8556 | K30: 8556 | L30: 8556 | M30: [객관 실적 / 추정 구간 고정] 차입금(단기·유동성장기·사채·장기) − 현금및현금성자산. 2022년 −12,455억 순현금에서 2025년 8,556억 순차입으로 3년 만에 뒤집혔다 — 자사주 매입·배당과 투자 확대가 겹친 결과다. 리스부채는 제외했다. 추정 구간은 2025년 수준으로 고정했다(배당·자사주 계획을 모델에 넣지 않았다).

Sheet Model
A1: KT&G 투자심사 모델
A2: 단위 억원 · 실적 4개년 + 추정 5개년
D3: 실적 | E3: 실적 | F3: 실적 | G3: 실적 | H3: 추정 | I3: 추정 | J3: 추정 | K3: 추정 | L3: 추정
A4: 계정 | B4: 노드 id | C4: 단위 | D4: 2022A | E4: 2023A | F4: 2024A | G4: 2025A | H4: 2026E | I4: 2027E | J4: 2028E | K4: 2029E | L4: 2030E
A5: 적정 시가총액 | B5: root | C5: 억원 | D5: =(D6-D52) | E5: =(E6-E52) | F5: =(F6-F52) | G5: =(G6-G52) | H5: =(H6-H52) | I5: =(I6-I52) | J5: =(J6-J52) | K5: =(K6-K52) | L5: =(L6-L52)
A6: 기업가치 (EV) | B6: ev | C6: 억원 | D6: =(D7+D50) | E6: =(E7+E50) | F6: =(F7+F50) | G6: =(G7+G50) | H6: =(H7+H50) | I6: =(I7+I50) | J6: =(J7+J50) | K6: =(K7+K50) | L6: =(L7+L50)
A7: 추정기간 PV 누적 | B7: cum_pv | C7: 억원 | D7: =(0+(D8*(1-D48))) | E7: =(D7+(E8*(1-E48))) | F7: =(E7+(F8*(1-F48))) | G7: =(F7+(G8*(1-G48))) | H7: =(G7+(H8*(1-H48))) | I7: =(H7+(I8*(1-I48))) | J7: =(I7+(J8*(1-J48))) | K7: =(J7+(K8*(1-K48))) | L7: =(K7+(L8*(1-L48)))
A8: FCF 현재가치 | B8: pv_fcf | C8: 억원 | D8: =(D9*D47) | E8: =(E9*E47) | F8: =(F9*F47) | G8: =(G9*G47) | H8: =(H9*H47) | I8: =(I9*I47) | J8: =(J9*J47) | K8: =(K9*K47) | L8: =(L9*L47)
A9: 잉여현금흐름 (FCF) | B9: fcf | C9: 억원 | D9: =((D10+D25)-D44) | E9: =((E10+E25)-E44) | F9: =((F10+F25)-F44) | G9: =((G10+G25)-G44) | H9: =((H10+H25)-H44) | I9: =((I10+I25)-I44) | J9: =((J10+J25)-J44) | K9: =((K10+K25)-K44) | L9: =((L10+L25)-L44)
A10: 세후영업이익 (NOPAT) | B10: nopat | C10: 억원 | D10: =(D12*(1-D11)) | E10: =(E12*(1-E11)) | F10: =(F12*(1-F11)) | G10: =(G12*(1-G11)) | H10: =(H12*(1-H11)) | I10: =(I12*(1-I11)) | J10: =(J12*(1-J11)) | K10: =(K12*(1-K11)) | L10: =(L12*(1-L11))
A11: 법인세율 | B11: tax_rate | C11: % | D11: 0.24 | E11: 0.24 | F11: 0.24 | G11: 0.24 | H11: 0.24 | I11: 0.24 | J11: 0.24 | K11: 0.24 | L11: 0.24
A12: 영업이익 | B12: op_profit | C12: 억원 | D12: =(D31-D24) | E12: =(E31-E24) | F12: =(F31-F24) | G12: =(G31-G24) | H12: =(H31-H24) | I12: =(I31-I24) | J12: =(J31-J24) | K12: =(K31-K24) | L12: =(L31-L24)
A13: EBITDA (참고) | B13: ebitda | C13: 억원 | D13: =(D12+D25) | E13: =(E12+E25) | F13: =(F12+F25) | G13: =(G12+G25) | H13: =(H12+H25) | I13: =(I12+I25) | J13: =(J12+J25) | K13: =(K12+K25) | L13: =(L12+L25)
A14: 지배주주 순이익 (참고) | B14: net_income | C14: 억원 | D14: =IF((D15>0),D16,(((D12+D17)*(1-D11))*D18)) | E14: =IF((E15>0),E16,(((E12+E17)*(1-E11))*E18)) | F14: =IF((F15>0),F16,(((F12+F17)*(1-F11))*F18)) | G14: =IF((G15>0),G16,(((G12+G17)*(1-G11))*G18)) | H14: =IF((H15>0),H16,(((H12+H17)*(1-H11))*H18)) | I14: =IF((I15>0),I16,(((I12+I17)*(1-I11))*I18)) | J14: =IF((J15>0),J16,(((J12+J17)*(1-J11))*J18)) | K14: =IF((K15>0),K16,(((K12+K17)*(1-K11))*K18)) | L14: =IF((L15>0),L16,(((L12+L17)*(1-L11))*L18))
A15: 순이익 실적 마스크 | B15: ni_hist | D15: 1 | E15: 1 | F15: 1 | G15: 1 | H15: 0 | I15: 0 | J15: 0 | K15: 0 | L15: 0
A16: 순이익 실적 | B16: ni_actual | C16: 억원 | D16: 10157.85 | E16: 9026.62 | F16: 11657.27 | G16: 10900.72 | H16: 0 | I16: 0 | J16: 0 | K16: 0 | L16: 0
A17: 영업외손익 | B17: nonop | C17: 억원 | D17: 1618.19 | E17: 810.82 | F17: 3770.25 | G17: 1115.91 | H17: 1200 | I17: 1200 | J17: 1200 | K17: 1200 | L17: 1200
A18: 지배지분 비율 | B18: ctrl_ratio | C18: % | D18: 0 | E18: 0 | F18: 0 | G18: 0 | H18: 0.99 | I18: 0.99 | J18: 0.99 | K18: 0.99 | L18: 0.99
A19: EPS (참고) | B19: eps | C19: 원 | D19: =((D14/D20)*100) | E19: =((E14/E20)*100) | F19: =((F14/F20)*100) | G19: =((G14/G20)*100) | H19: =((H14/H20)*100) | I19: =((I14/I20)*100) | J19: =((J14/J20)*100) | K19: =((K14/K20)*100) | L19: =((L14/L20)*100)
A20: 상장주식수 | B20: shares | C20: 백만주 | D20: 103.81046 | E20: 103.81046 | F20: 103.81046 | G20: 103.81046 | H20: 103.81046 | I20: 103.81046 | J20: 103.81046 | K20: 103.81046 | L20: 103.81046
A21: DPS (참고) | B21: dps | C21: 원 | D21: =IF((D15>0),D22,(D19*D23)) | E21: =IF((E15>0),E22,(E19*E23)) | F21: =IF((F15>0),F22,(F19*F23)) | G21: =IF((G15>0),G22,(G19*G23)) | H21: =IF((H15>0),H22,(H19*H23)) | I21: =IF((I15>0),I22,(I19*I23)) | J21: =IF((J15>0),J22,(J19*J23)) | K21: =IF((K15>0),K22,(K19*K23)) | L21: =IF((L15>0),L22,(L19*L23))
A22: DPS 실적 | B22: dps_a | C22: 원 | D22: 5000 | E22: 5200 | F22: 5400 | G22: 6000 | H22: 0 | I22: 0 | J22: 0 | K22: 0 | L22: 0
A23: 배당성향 | B23: payout | C23: % | D23: 0 | E23: 0 | F23: 0 | G23: 0 | H23: 0.57 | I23: 0.57 | J23: 0.57 | K23: 0.57 | L23: 0.57
A24: 총비용 | B24: total_cost | C24: 억원 | D24: =(D25+D28) | E24: =(E25+E28) | F24: =(F25+F28) | G24: =(G25+G28) | H24: =(H25+H28) | I24: =(I25+I28) | J24: =(J25+J28) | K24: =(K25+K28) | L24: =(L25+L28)
A25: 감가상각비 | B25: dep_total | C25: 억원 | D25: =IF((D26>0),D26,(0*(1+D27))) | E25: =IF((E26>0),E26,(D25*(1+E27))) | F25: =IF((F26>0),F26,(E25*(1+F27))) | G25: =IF((G26>0),G26,(F25*(1+G27))) | H25: =IF((H26>0),H26,(G25*(1+H27))) | I25: =IF((I26>0),I26,(H25*(1+I27))) | J25: =IF((J26>0),J26,(I25*(1+J27))) | K25: =IF((K26>0),K26,(J25*(1+K27))) | L25: =IF((L26>0),L26,(K25*(1+L27)))
A26: 감가상각비 실적 | B26: dep_actual | C26: 억원 | D26: 2341 | E26: 2515 | F26: 2626 | G26: 3043 | H26: 0 | I26: 0 | J26: 0 | K26: 0 | L26: 0
A27: 감가상각 증가율 | B27: dep_g | C27: % | D27: 0 | E27: 0 | F27: 0 | G27: 0 | H27: 0.09 | I27: 0.07 | J27: 0.05 | K27: 0.04 | L27: 0.03
A28: 기타비용 | B28: other_cost | C28: 억원 | D28: =IF((D29>0),D29,(D31*D30)) | E28: =IF((E29>0),E29,(E31*E30)) | F28: =IF((F29>0),F29,(F31*F30)) | G28: =IF((G29>0),G29,(G31*G30)) | H28: =IF((H29>0),H29,(H31*H30)) | I28: =IF((I29>0),I29,(I31*I30)) | J28: =IF((J29>0),J29,(J31*J30)) | K28: =IF((K29>0),K29,(K31*K30)) | L28: =IF((L29>0),L29,(L31*L30))
A29: 기타비용 실적 | B29: other_actual | C29: 억원 | D29: 43496 | E29: 44438 | F29: 44574 | G29: 49317 | H29: 0 | I29: 0 | J29: 0 | K29: 0 | L29: 0
A30: 기타비용률 | B30: other_ratio | C30: % | D30: 0 | E30: 0 | F30: 0 | G30: 0 | H30: 0.75 | I30: 0.749 | J30: 0.748 | K30: 0.747 | L30: 0.746
A31: 총매출 | B31: total_revenue | C31: 억원 | D31: =(((D32+D35)+D38)+D41) | E31: =(((E32+E35)+E38)+E41) | F31: =(((F32+F35)+F38)+F41) | G31: =(((G32+G35)+G38)+G41) | H31: =(((H32+H35)+H38)+H41) | I31: =(((I32+I35)+I38)+I41) | J31: =(((J32+J35)+J38)+J41) | K31: =(((K32+K35)+K38)+K41) | L31: =(((L32+L35)+L38)+L41)
A32: 담배 | B32: tobacco | C32: 억원 | D32: =IF((D33>0),D33,(0*(1+D34))) | E32: =IF((E33>0),E33,(D32*(1+E34))) | F32: =IF((F33>0),F33,(E32*(1+F34))) | G32: =IF((G33>0),G33,(F32*(1+G34))) | H32: =IF((H33>0),H33,(G32*(1+H34))) | I32: =IF((I33>0),I33,(H32*(1+I34))) | J32: =IF((J33>0),J33,(I32*(1+J34))) | K32: =IF((K33>0),K33,(J32*(1+K34))) | L32: =IF((L33>0),L33,(K32*(1+L34)))
A33: 담배 실적 | B33: tob_actual | C33: 억원 | D33: 35738 | E33: 36123 | F33: 39056 | G33: 43672 | H33: 0 | I33: 0 | J33: 0 | K33: 0 | L33: 0
A34: 담배 성장률 | B34: tob_g | C34: % | D34: 0 | E34: 0 | F34: 0 | G34: 0 | H34: 0.07 | I34: 0.06 | J34: 0.05 | K34: 0.04 | L34: 0.03
A35: 인삼 (KGC) | B35: ginseng | C35: 억원 | D35: =IF((D36>0),D36,(0*(1+D37))) | E35: =IF((E36>0),E36,(D35*(1+E37))) | F35: =IF((F36>0),F36,(E35*(1+F37))) | G35: =IF((G36>0),G36,(F35*(1+G37))) | H35: =IF((H36>0),H36,(G35*(1+H37))) | I35: =IF((I36>0),I36,(H35*(1+I37))) | J35: =IF((J36>0),J36,(I35*(1+J37))) | K35: =IF((K36>0),K36,(J35*(1+K37))) | L35: =IF((L36>0),L36,(K35*(1+L37)))
A36: 인삼 실적 | B36: gin_actual | C36: 억원 | D36: 13890 | E36: 13935 | F36: 13016 | G36: 11370 | H36: 0 | I36: 0 | J36: 0 | K36: 0 | L36: 0
A37: 인삼 성장률 | B37: gin_g | C37: % | D37: 0 | E37: 0 | F37: 0 | G37: 0 | H37: -0.03 | I37: 0 | J37: 0.01 | K37: 0.01 | L37: 0.01
A38: 부동산 | B38: estate | C38: 억원 | D38: =IF((D39>0),D39,(0*(1+D40))) | E38: =IF((E39>0),E39,(D38*(1+E40))) | F38: =IF((F39>0),F39,(E38*(1+F40))) | G38: =IF((G39>0),G39,(F38*(1+G40))) | H38: =IF((H39>0),H39,(G38*(1+H40))) | I38: =IF((I39>0),I39,(H38*(1+I40))) | J38: =IF((J39>0),J39,(I38*(1+J40))) | K38: =IF((K39>0),K39,(J38*(1+K40))) | L38: =IF((L39>0),L39,(K38*(1+L40)))
A39: 부동산 실적 | B39: est_actual | C39: 억원 | D39: 6071 | E39: 5501 | F39: 3613 | G39: 7127 | H39: 0 | I39: 0 | J39: 0 | K39: 0 | L39: 0
A40: 부동산 성장률 | B40: est_g | C40: % | D40: 0 | E40: 0 | F40: 0 | G40: 0 | H40: -0.2 | I40: -0.02 | J40: 0 | K40: 0 | L40: 0
...

Sheet Formula Audit
A1: 수식 감사
A2: 모델 원식 ↔ Excel 셀 수식 대조. 변환은 엔진의 astToExcel이 담당한다.
A4: 노드 id | B4: 계정 | C4: 행 | D4: 모델 원식 | E4: 첫 추정연도 셀 수식
A5: root | B5: 적정 시가총액 | C5: 5 | D5: ev - net_debt | E5: '=(H6-H52)
A6: ev | B6: 기업가치 (EV) | C6: 6 | D6: cum_pv + tv_pv | E6: '=(H7+H50)
A7: cum_pv | B7: 추정기간 PV 누적 | C7: 7 | D7: PREV(cum_pv) + pv_fcf * (1 - df_hist) | E7: '=(G7+(H8*(1-H48)))
A8: pv_fcf | B8: FCF 현재가치 | C8: 8 | D8: fcf * df | E8: '=(H9*H47)
A9: fcf | B9: 잉여현금흐름 (FCF) | C9: 9 | D9: nopat + dep_total - capex | E9: '=((H10+H25)-H44)
A10: nopat | B10: 세후영업이익 (NOPAT) | C10: 10 | D10: op_profit * (1 - tax_rate) | E10: '=(H12*(1-H11))
A11: op_profit | B11: 영업이익 | C11: 12 | D11: total_revenue - total_cost | E11: '=(H31-H24)
A12: ebitda | B12: EBITDA (참고) | C12: 13 | D12: op_profit + dep_total | E12: '=(H12+H25)
A13: net_income | B13: 지배주주 순이익 (참고) | C13: 14 | D13: IF(ni_hist > 0, ni_actual, (op_profit + nonop) * (1 - tax_rate) * ctrl_ratio) | E13: '=IF((H15>0),H16,(((H12+H17)*(1-H11))*H18))
A14: eps | B14: EPS (참고) | C14: 19 | D14: net_income / shares * 100 | E14: '=((H14/H20)*100)
A15: dps | B15: DPS (참고) | C15: 21 | D15: IF(ni_hist > 0, dps_a, eps * payout) | E15: '=IF((H15>0),H22,(H19*H23))
A16: total_cost | B16: 총비용 | C16: 24 | D16: dep_total + other_cost | E16: '=(H25+H28)
... A26: tv_pv | B26: 잔존가치 PV | C26: 50 | D26: fcf * (1 + tv_growth) / (wacc - tv_growth) * df | E26: '=(((H9*(1+H51))/(H49-H51))*H47)

Sheet Structure
A1: 트리 구조
A3: 노드 id | B3: 계정 | C3: 깊이 | D3: 유형 | E3: 합계형 | F3: 행 | G3: 단위
A4: root | B4: 적정 시가총액 | C4: 0 | D4: computed | F4: 5 | G4: 억원
A5: ev | B5: 기업가치 (EV) | C5: 1 | D5: computed | E5: Y | F5: 6 | G5: 억원
A6: cum_pv | B6: 추정기간 PV 누적 | C6: 2 | D6: computed | F6: 7 | G6: 억원
A7: pv_fcf | B7: FCF 현재가치 | C7: 3 | D7: computed | F7: 8 | G7: 억원
A8: fcf | B8: 잉여현금흐름 (FCF) | C8: 4 | D8: computed | F8: 9 | G8: 억원
A9: nopat | B9: 세후영업이익 (NOPAT) | C9: 5 | D9: computed | F9: 10 | G9: 억원
A10: tax_rate | B10: 법인세율 | C10: 6 | D10: input | F10: 11 | G10: %
A11: op_profit | B11: 영업이익 | C11: 6 | D11: computed | F11: 12 | G11: 억원
A12: ebitda | B12: EBITDA (참고) | C12: 7 | D12: computed | F12: 13 | G12: 억원
A13: net_income | B13: 지배주주 순이익 (참고) | C13: 7 | D13: computed | F13: 14 | G13: 억원
A14: ni_hist | B14: 순이익 실적 마스크 | C14: 8 | D14: input | F14: 15
A15: ni_actual | B15: 순이익 실적 | C15: 8 | D15: input | F15: 16 | G15: 억원
A16: nonop | B16: 영업외손익 | C16: 8 | D16: input | F16: 17 | G16: 억원
A17: ctrl_ratio | B17: 지배지분 비율 | C17: 8 | D17: input | F17: 18 | G17: %
A18: eps | B18: EPS (참고) | C18: 8 | D18: computed | F18: 19 | G18: 원
A19: shares | B19: 상장주식수 | C19: 9 | D19: input | F19: 20 | G19: 백만주
A20: dps | B20: DPS (참고) | C20: 9 | D20: computed | F20: 21 | G20: 원
A21: dps_a | B21: DPS 실적 | C21: 10 | D21: input | F21: 22 | G21: 원
A22: payout | B22: 배당성향 | C22: 10 | D22: input | F22: 23 | G22: %
A23: total_cost | B23: 총비용 | C23: 7 | D23: computed | E23: Y | F23: 24 | G23: 억원
A24: dep_total | B24: 감가상각비 | C24: 8 | D24: computed | F24: 25 | G24: 억원
A25: dep_actual | B25: 감가상각비 실적 | C25: 9 | D25: input | F25: 26 | G25: 억원
A26: dep_g | B26: 감가상각 증가율 | C26: 9 | D26: input | F26: 27 | G26: %
A27: other_cost | B27: 기타비용 | C27: 8 | D27: computed | F27: 28 | G27: 억원
A28: other_actual | B28: 기타비용 실적 | C28: 9 | D28: input | F28: 29 | G28: 억원
A29: other_ratio | B29: 기타비용률 | C29: 9 | D29: input | F29: 30 | G29: %
A30: total_revenue | B30: 총매출 | C30: 7 | D30: computed | E30: Y | F30: 31 | G30: 억원
A31: tobacco | B31: 담배 | C31: 8 | D31: computed | F31: 32 | G31: 억원
A32: tob_actual | B32: 담배 실적 | C32: 9 | D32: input | F32: 33 | G32: 억원
A33: tob_g | B33: 담배 성장률 | C33: 9 | D33: input | F33: 34 | G33: %
A34: ginseng | B34: 인삼 (KGC) | C34: 8 | D34: computed | F34: 35 | G34: 억원
A35: gin_actual | B35: 인삼 실적 | C35: 9 | D35: input | F35: 36 | G35: 억원
A36: gin_g | B36: 인삼 성장률 | C36: 9 | D36: input | F36: 37 | G36: %
A37: estate | B37: 부동산 | C37: 8 | D37: computed | F37: 38 | G37: 억원
A38: est_actual | B38: 부동산 실적 | C38: 9 | D38: input | F38: 39 | G38: 억원
A39: est_g | B39: 부동산 성장률 | C39: 9 | D39: input | F39: 40 | G39: %
A40: etc | B40: 기타 | C40: 8 | D40: computed | F40: 41 | G40: 억원
A41: etc_actual | B41: 기타 실적 | C41: 9 | D41: input | F41: 42 | G41: 억원
...

Sheet Checks
A1: 검증
A2: 합계형 노드의 부모값과 자식 합의 차이. 전 칸이 0이어야 한다.
D3: 실적 | E3: 실적 | F3: 실적 | G3: 실적 | H3: 추정 | I3: 추정 | J3: 추정 | K3: 추정 | L3: 추정
A4: 계정 | B4: 검사 | D4: 2022A | E4: 2023A | F4: 2024A | G4: 2025A | H4: 2026E | I4: 2027E | J4: 2028E | K4: 2029E | L4: 2030E
A5: 기업가치 (EV) | B5: 부모 − 자식합 | D5: =ROUND(Model!D6-(Model!D7+Model!D50),6) | E5: =ROUND(Model!E6-(Model!E7+Model!E50),6) | F5: =ROUND(Model!F6-(Model!F7+Model!F50),6) | G5: =ROUND(Model!G6-(Model!G7+Model!G50),6) | H5: =ROUND(Model!H6-(Model!H7+Model!H50),6) | I5: =ROUND(Model!I6-(Model!I7+Model!I50),6) | J5: =ROUND(Model!J6-(Model!J7+Model!J50),6) | K5: =ROUND(Model!K6-(Model!K7+Model!K50),6) | L5: =ROUND(Model!L6-(Model!L7+Model!L50),6)
A6: 총비용 | B6: 부모 − 자식합 | D6: =ROUND(Model!D24-(Model!D25+Model!D28),6) | E6: =ROUND(Model!E24-(Model!E25+Model!E28),6) | F6: =ROUND(Model!F24-(Model!F25+Model!F28),6) | G6: =ROUND(Model!G24-(Model!G25+Model!G28),6) | H6: =ROUND(Model!H24-(Model!H25+Model!H28),6) | I6: =ROUND(Model!I24-(Model!I25+Model!I28),6) | J6: =ROUND(Model!J24-(Model!J25+Model!J28),6) | K6: =ROUND(Model!K24-(Model!K25+Model!K28),6) | L6: =ROUND(Model!L24-(Model!L25+Model!L28),6)
A7: 총매출 | B7: 부모 − 자식합 | D7: =ROUND(Model!D31-(Model!D32+Model!D35+Model!D38+Model!D41),6) | E7: =ROUND(Model!E31-(Model!E32+Model!E35+Model!E38+Model!E41),6) | F7: =ROUND(Model!F31-(Model!F32+Model!F35+Model!F38+Model!F41),6) | G7: =ROUND(Model!G31-(Model!G32+Model!G35+Model!G38+Model!G41),6) | H7: =ROUND(Model!H31-(Model!H32+Model!H35+Model!H38+Model!H41),6) | I7: =ROUND(Model!I31-(Model!I32+Model!I35+Model!I38+Model!I41),6) | J7: =ROUND(Model!J31-(Model!J32+Model!J35+Model!J38+Model!J41),6) | K7: =ROUND(Model!K31-(Model!K32+Model!K35+Model!K38+Model!K41),6) | L7: =ROUND(Model!L31-(Model!L32+Model!L35+Model!L38+Model!L41),6)
A9: 합계형 노드 수 | B9: 3

Sheet Metadata
A1: 빌드 정보
A3: 소스 | B3: model.html
A4: 소스 해시 (sha256 앞 16자리) | B4: d05b62086640f711
A5: 빌더 | B5: tools/build_excel.py
A6: 수식 변환 | B6: 엔진 astToExcel (JS) — 파이썬은 배치만 한다
A7: 노드 수 | B7: 48
A8: 입력 노드 수 | B8: 26
A9: 연도 수 | B9: 9
A10: HIST_N | B10: 4
A11: 모델 id | B11: ktg_dcf
